Workbook

Sheet 변경요약
A1: 한국ST거래 메뉴구조·기능정의 v2 — 변경 요약
A2: 기준: Git 프로토타입 화면 148개(v1) → v2 152개(신규 4). 아래 집계는 시트 값에서 자동 계산됩니다.
A4: 변경구분 | B4: 정의 | C4: 색상 | D4: 화면 수 | E4: 기능정의 행 수
A5: 신규 | B5: 새로 추가된 화면·기능 | D5: =COUNTIF(메뉴구조!$K$5:$K$156,A5) -> 4 | E5: =COUNTIF('기능정의 상세'!$K$4:$K$714,A5) -> 35
A6: 수정 | B6: 화면 내용·표시 방식·문구가 바뀜 | D6: =COUNTIF(메뉴구조!$K$5:$K$156,A6) -> 69 | E6: =COUNTIF('기능정의 상세'!$K$4:$K$714,A6) -> 119
A7: 이동 | B7: 메뉴 위치(경로)가 바뀜 — 상세 시트 경로는 자동 반영 | D7: =COUNTIF(메뉴구조!$K$5:$K$156,A7) -> 14 | E7: =COUNTIF('기능정의 상세'!$K$4:$K$714,A7) -> 64
A8: 명칭변경 | B8: 메뉴명만 바뀜 — 상세 시트 경로는 자동 반영 | D8: =COUNTIF(메뉴구조!$K$5:$K$156,A8) -> 33 | E8: =COUNTIF('기능정의 상세'!$K$4:$K$714,A8) -> 144
A9: 삭제 | B9: v2에서 제거(다른 화면으로 통합 포함). 이력 보존을 위해 행은 남김 | D9: =COUNTIF(메뉴구조!$K$5:$K$156,A9) -> 2 | E9: =COUNTIF('기능정의 상세'!$K$4:$K$714,A9) -> 34
A10: 유지 | B10: 변경 없음 | D10: =COUNTIF(메뉴구조!$K$5:$K$156,A10) -> 30 | E10: =COUNTIF('기능정의 상세'!$K$4:$K$714,A10) -> 315
A11: 합계 | D11: =SUM(D5:D10) -> 152 | E11: =SUM(E5:E10) -> 711
A12: 유효 화면(삭제 제외) | D12: =D11-D9 -> 150 | E12: =E11-E9 -> 677
A14: v2 메뉴 트리 (하단 탭 5개)
A15: 홈 · 백년가게 · 거래 · MY · 더보기 (알림·검색은 탭이 아닌 진입 화면)
A17: 거래 ─ 종목(목록 + 검색 영역 + 필터 시트) ─ 종목상세(정보/주문(간편·일반)/호가/차트/내 주문/커뮤니티)
A18: MY ─ 허브(프로필·투자성향 칩 → 내 자산 카드 → 관심 → 활동 → 내 정보·투자자 자격 신청)
A19: ├ 내 자산: 보유 | 주문 내역 | 손익 현황 | 거래 한도 (공통 헤더: 계좌 셀렉터·평가금·잔고, 계좌 변경 바텀시트)
A20: ├ 관심: 관심종목 | 관심가게
A21: ├ 활동 내역: 커뮤니티(게시글|댓글) | 문의내역
A22: ├ 내 정보(재인증): 기본 정보 수정 · 투자 성향 분석(실시 Q1~Q6, 결과) · 투자자 자격 신청(서류 제출, 개인정보 동의)
A23: └ 설정: 정보설정 · 회원탈퇴
A24: 더보기(그룹 없는 1단 목록) ─ 공지사항 · 이벤트 · 이용안내 · 고객센터 · 투자자 유의사항 · 약관 및 정책(하위 4종) · 회사소개 ↗ · 앱 버전
A25: 검색 ─ 검색 홈 · 검색 결과(종목|가게) ※ 진입: 홈·백년가게(탐색)·거래 상단 검색 영역
A27: 메뉴명을 바꾸는 방법
... A31: 4) 기능정의 상세의 설명·정책 본문 안에 적힌 메뉴명(예: '거래 > 관심')은 수식이 아니므로 별도로 수정해야 합니다.

Sheet 메뉴구조
A1: 한국ST거래 프론트 IA — 메뉴구조 v2 (MY 자산 중심 개편)
A2: 메뉴명은 이 시트의 B~E열에서만 수정하세요. '기능정의 상세' 시트의 1~4Depth·전체 경로는 화면ID로 자동 연동됩니다. 변경구분·변경 전 경로·변경 내용은 v1(2026.09.27 Git 기준) 대비 변경 이력입니다.
A4: 화면ID | B4: 1Depth | C4: 2Depth | D4: 3Depth | E4: 4Depth | F4: 화면구분 | G4: 화면(전체 경로) | H4: 로그인후 | I4: 기능정의수 | J4: 상태 | K4: 변경구분 | L4: 변경 전 경로 | M4: 변경 내용 | N4: 비고 | O4: 확인 필요
A5: S001 | B5: 스플래시 | C5: — | D5: — | E5: — | F5: 상세 | G5: =B5&IF(OR(C5="",C5="—"),"", " / "&C5)&IF(OR(D5="",D5="—"),"", " / "&D5)&IF(OR(E5="",E5="—"),"", " / "&E5) -> 스플래시 | H5: Y | I5: =COUNTIFS('기능정의 상세'!$A$4:$A$1200,A5,'기능정의 상세'!$K$4:$K$1200,"<>삭제") -> 6 | J5: 편집중 | K5: 유지 | O5: 화면구분 추정
A6: S002 | B6: 회원가입 | C6: 약관동의 | D6: — | E6: — | F6: 상세 | G6: =B6&IF(OR(C6="",C6="—"),"", " / "&C6)&IF(OR(D6="",D6="—"),"", " / "&D6)&IF(OR(E6="",E6="—"),"", " / "&E6) -> 회원가입 / 약관동의 | H6: Y | I6: =COUNTIFS('기능정의 상세'!$A$4:$A$1200,A6,'기능정의 상세'!$K$4:$K$1200,"<>삭제") -> 5 | J6: 초안 | K6: 유지
A7: S003 | B7: 회원가입 | C7: 본인인증_정책 | D7: — | E7: — | F7: 상세 | G7: =B7&IF(OR(C7="",C7="—"),"", " / "&C7)&IF(OR(D7="",D7="—"),"", " / "&D7)&IF(OR(E7="",E7="—"),"", " / "&E7) -> 회원가입 / 본인인증_정책 | I7: =COUNTIFS('기능정의 상세'!$A$4:$A$1200,A7,'기능정의 상세'!$K$4:$K$1200,"<>삭제") -> 4 | J7: 편집중 | K7: 유지 | O7: 화면구분 추정
A8: S004 | B8: 회원가입 | C8: 회원정보 입력 | D8: — | E8: — | F8: 상세 | G8: =B8&IF(OR(C8="",C8="—"),"", " / "&C8)&IF(OR(D8="",D8="—"),"", " / "&D8)&IF(OR(E8="",E8="—"),"", " / "&E8) -> 회원가입 / 회원정보 입력 | H8: Y | I8: =COUNTIFS('기능정의 상세'!$A$4:$A$1200,A8,'기능정의 상세'!$K$4:$K$1200,"<>삭제") -> 0 | J8: 초안 | K8: 유지
A9: S005 | B9: 회원가입 | C9: 로그인설정 (생체) | D9: — | E9: — | F9: 상세 | G9: =B9&IF(OR(C9="",C9="—"),"", " / "&C9)&IF(OR(D9="",D9="—"),"", " / "&D9)&IF(OR(E9="",E9="—"),"", " / "&E9) -> 회원가입 / 로그인설정 (생체) | I9: =COUNTIFS('기능정의 상세'!$A$4:$A$1200,A9,'기능정의 상세'!$K$4:$K$1200,"<>삭제") -> 6 | J9: 편집중 | K9: 유지 | O9: 화면구분 추정
A10: S006 | B10: 회원가입 | C10: 투자정보 입력 | D10: — | E10: — | F10: 상세 | G10: =B10&IF(OR(C10="",C10="—"),"", " / "&C10)&IF(OR(D10="",D10="—"),"", " / "&D10)&IF(OR(E10="",E10="—"),"", " / "&E10) -> 회원가입 / 투자정보 입력 | I10: =COUNTIFS('기능정의 상세'!$A$4:$A$1200,A10,'기능정의 상세'!$K$4:$K$1200,"<>삭제") -> 7 | J10: 편집중 | K10: 유지
A11: S007 | B11: 회원가입 | C11: 투자정보 입력 2 | D11: — | E11: — | F11: 상세 | G11: =B11&IF(OR(C11="",C11="—"),"", " / "&C11)&IF(OR(D11="",D11="—"),"", " / "&D11)&IF(OR(E11="",E11="—"),"", " / "&E11) -> 회원가입 / 투자정보 입력 2 | I11: =COUNTIFS('기능정의 상세'!$A$4:$A$1200,A11,'기능정의 상세'!$K$4:$K$1200,"<>삭제") -> 11 | J11: 편집중 | K11: 유지 | O11: 화면구분 추정
A12: S008 | B12: 회원가입 | C12: 가입완료 | D12: — | E12: — | F12: 상세 | G12: =B12&IF(OR(C12="",C12="—"),"", " / "&C12)&IF(OR(D12="",D12="—"),"", " / "&D12)&IF(OR(E12="",E12="—"),"", " / "&E12) -> 회원가입 / 가입완료 | I12: =COUNTIFS('기능정의 상세'!$A$4:$A$1200,A12,'기능정의 상세'!$K$4:$K$1200,"<>삭제") -> 9 | J12: 편집중 | K12: 유지 | N12: 이용안내 링크 추가 (STEP2 반영)
A13: S009 | B13: 회원가입 | C13: 로그인설정 (생체) | D13: — | E13: — | F13: 상세 | G13: =B13&IF(OR(C13="",C13="—"),"", " / "&C13)&IF(OR(D13="",D13="—"),"", " / "&D13)&IF(OR(E13="",E13="—"),"", " / "&E13) -> 회원가입 / 로그인설정 (생체) | I13: =COUNTIFS('기능정의 상세'!$A$4:$A$1200,A13,'기능정의 상세'!$K$4:$K$1200,"<>삭제") -> 6 | J13: 편집중 | K13: 유지 | O13: 화면구분 추정
A14: S010 | B14: 로그인 | C14: 로그인 | D14: — | E14: — | F14: 상세 | G14: =B14&IF(OR(C14="",C14="—"),"", " / "&C14)&IF(OR(D14="",D14="—"),"", " / "&D14)&IF(OR(E14="",E14="—"),"", " / "&E14) -> 로그인 / 로그인 | H14: Y | I14: =COUNTIFS('기능정의 상세'!$A$4:$A$1200,A14,'기능정의 상세'!$K$4:$K$1200,"<>삭제") -> 7 | J14: 초안 | K14: 유지
A15: S011 | B15: 로그인 | C15: 다른방법으로로그인 | D15: — | E15: — | F15: 상세 | G15: =B15&IF(OR(C15="",C15="—"),"", " / "&C15)&IF(OR(D15="",D15="—"),"", " / "&D15)&IF(OR(E15="",E15="—"),"", " / "&E15) -> 로그인 / 다른방법으로로그인 | I15: =COUNTIFS('기능정의 상세'!$A$4:$A$1200,A15,'기능정의 상세'!$K$4:$K$1200,"<>삭제") -> 5 | J15: 초안 | K15: 유지 | O15: 화면구분 추정
A16: S012 | B16: 홈 | C16: — | D16: — | E16: — | F16: 메인 | G16: =B16&IF(OR(C16="",C16="—"),"", " / "&C16)&IF(OR(D16="",D16="—"),"", " / "&D16)&IF(OR(E16="",E16="—"),"", " / "&E16) -> 홈 | H16: Y | I16: =COUNTIFS('기능정의 상세'!$A$4:$A$1200,A16,'기능정의 상세'!$K$4:$K$1200,"<>삭제") -> 12 | J16: 초안 | K16: 수정 | M16: 상단 검색 영역 추가(R-07) · 이벤트 섹션명 '이벤트'로 통일 · 관심 아이콘 하트 통일(R-12) | N16: 이용안내 진입 배너 추가 (홈 하단) ← STEP2 반영
A17: S013 | B17: 홈 | C17: 로그인 후 | D17: — | E17: — | F17: 상세 | G17: =B17&IF(OR(C17="",C17="—"),"", " / "&C17)&IF(OR(D17="",D17="—"),"", " / "&D17)&IF(OR(E17="",E17="—"),"", " / "&E17) -> 홈 / 로그인 후 | I17: =COUNTIFS('기능정의 상세'!$A$4:$A$1200,A17,'기능정의 상세'!$K$4:$K$1200,"<>삭제") -> 3 | J17: 초안 | K17: 유지 | O17: 화면구분 추정
A18: S014 | B18: 홈 | C18: 로그인 후 | D18: — | E18: — | F18: 상세 | G18: =B18&IF(OR(C18="",C18="—"),"", " / "&C18)&IF(OR(D18="",D18="—"),"", " / "&D18)&IF(OR(E18="",E18="—"),"", " / "&E18) -> 홈 / 로그인 후 | I18: =COUNTIFS('기능정의 상세'!$A$4:$A$1200,A18,'기능정의 상세'!$K$4:$K$1200,"<>삭제") -> 1 | J18: 초안 | K18: 수정 | M18: 내 자산 띠 이동 대상 변경: 거래 > 보유 → MY > 내 자산 | O18: 화면구분 추정
A19: S015 | B19: 백년가게 | C19: 탐색 | D19: 목록 | E19: — | F19: 목록 | G19: =B19&IF(OR(C19="",C19="—"),"", " / "&C19)&IF(OR(D19="",D19="—"),"", " / "&D19)&IF(OR(E19="",E19="—"),"", " / "&E19) -> 백년가게 / 탐색 / 목록 | H19: Y | I19: =COUNTIFS('기능정의 상세'!$A$4:$A$1200,A19,'기능정의 상세'!$K$4:$K$1200,"<>삭제") -> 5 | J19: 초안 | K19: 수정 | M19: 상단 검색 영역 추가(R-07) · 찜 안내 문구를 MY > 관심으로 수정
A20: S016 | B20: 백년가게 | C20: 탐색 | D20: 가게 상세 | E20: 정보 | F20: 탭(상세) | G20: =B20&IF(OR(C20="",C20="—"),"", " / "&C20)&IF(OR(D20="",D20="—"),"", " / "&D20)&IF(OR(E20="",E20="—"),"", " / "&E20) -> 백년가게 / 탐색 / 가게 상세 / 정보 | H20: Y | I20: =COUNTIFS('기능정의 상세'!$A$4:$A$1200,A20,'기능정의 상세'!$K$4:$K$1200,"<>삭제") -> 8 | J20: 초안 | K20: 수정 | M20: 찜 안내 문구를 MY > 관심으로 수정
A21: S017 | B21: 백년가게 | C21: 탐색 | D21: 가게 상세 | E21: 종목 | F21: 탭(목록) | G21: =B21&IF(OR(C21="",C21="—"),"", " / "&C21)&IF(OR(D21="",D21="—"),"", " / "&D21)&IF(OR(E21="",E21="—"),"", " / "&E21) -> 백년가게 / 탐색 / 가게 상세 / 종목 | H21: Y | I21: =COUNTIFS('기능정의 상세'!$A$4:$A$1200,A21,'기능정의 상세'!$K$4:$K$1200,"<>삭제") -> 4 | J21: 초안 | K21: 유지
A22: S018 | B22: 백년가게 | C22: 탐색 | D22: 가게 상세 | E22: 커뮤니티 | F22: 탭(목록) | G22: =B22&IF(OR(C22="",C22="—"),"", " / "&C22)&IF(OR(D22="",D22="—"),"", " / "&D22)&IF(OR(E22="",E22="—"),"", " / "&E22) -> 백년가게 / 탐색 / 가게 상세 / 커뮤니티 | H22: Y | I22: =COUNTIFS('기능정의 상세'!$A$4:$A$1200,A22,'기능정의 상세'!$K$4:$K$1200,"<>삭제") -> 4 | J22: 초안 | K22: 유지
A23: S019 | B23: 백년가게 | C23: 탐색 | D23: 가게 상세 | E23: 혜택 | F23: 탭(상세) | G23: =B23&IF(OR(C23="",C23="—"),"", " / "&C23)&IF(OR(D23="",D23="—"),"", " / "&D23)&IF(OR(E23="",E23="—"),"", " / "&E23) -> 백년가게 / 탐색 / 가게 상세 / 혜택 | H23: Y | I23: =COUNTIFS('기능정의 상세'!$A$4:$A$1200,A23,'기능정의 상세'!$K$4:$K$1200,"<>삭제") -> 1 | J23: 초안 | K23: 유지
A24: S020 | B24: 백년가게 | C24: 내 주변 | D24: — | E24: — | F24: 목록 | G24: =B24&IF(OR(C24="",C24="—"),"", " / "&C24)&IF(OR(D24="",D24="—"),"", " / "&D24)&IF(OR(E24="",E24="—"),"", " / "&E24) -> 백년가게 / 내 주변 | H24: Y | I24: =COUNTIFS('기능정의 상세'!$A$4:$A$1200,A24,'기능정의 상세'!$K$4:$K$1200,"<>삭제") -> 5 | J24: 초안 | K24: 유지
A25: S021 | B25: 백년가게 | C25: 백년가게? | D25: — | E25: — | F25: 상세 | G25: =B25&IF(OR(C25="",C25="—"),"", " / "&C25)&IF(OR(D25="",D25="—"),"", " / "&D25)&IF(OR(E25="",E25="—"),"", " / "&E25) -> 백년가게 / 백년가게? | H25: Y | I25: =COUNTIFS('기능정의 상세'!$A$4:$A$1200,A25,'기능정의 상세'!$K$4:$K$1200,"<>삭제") -> 1 | J25: 초안 | K25: 유지
A26: S023 | B26: 거래 | C26: 종목 | D26: — | E26: — | F26: 목록 | G26: =B26&IF(OR(C26="",C26="—"),"", " / "&C26)&IF(OR(D26="",D26="—"),"", " / "&D26)&IF(OR(E26="",E26="—"),"", " / "&E26) -> 거래 / 종목 | H26: Y | I26: =COUNTIFS('기능정의 상세'!$A$4:$A$1200,A26,'기능정의 상세'!$K$4:$K$1200,"<>삭제") -> 11 | J26: 편집중 | K26: 수정 | L26: 거래 / 전체 | M26: 2Depth '전체'→'종목' · 세그먼트(전체/보유/관심) 제거 · 정렬 팝업(S149)·관심만 칩·검색 영역 추가 | N26: 상장 종목 목록 + 정렬 팝업 + '관심만' 칩. 보유 종목·주문 내역은 MY > 내 자산으로 이동
A27: S149 | B27: 거래 | C27: 종목 | D27: 정렬 | E27: — | F27: 팝업 | G27: =B27&IF(OR(C27="",C27="—"),"", " / "&C27)&IF(OR(D27="",D27="—"),"", " / "&D27)&IF(OR(E27="",E27="—"),"", " / "&E27) -> 거래 / 종목 / 정렬 | I27: =COUNTIFS('기능정의 상세'!$A$4:$A$1200,A27,'기능정의 상세'!$K$4:$K$1200,"<>삭제") -> 3 | J27: 초안 | K27: 신규 | M27: 거래 종목 목록의 정렬 팝업 신규 정의(R-02, 정렬만 있는 경우 팝업) | N27: 정렬 6종 단일 선택, 탭 즉시 적용. '관심만 보기'는 목록 상단 칩(S023)
A28: S024 | B28: 거래 | C28: 종목 | D28: 종목상세 | E28: 정보 | F28: 탭(상세) | G28: =B28&IF(OR(C28="",C28="—"),"", " / "&C28)&IF(OR(D28="",D28="—"),"", " / "&D28)&IF(OR(E28="",E28="—"),"", " / "&E28) -> 거래 / 종목 / 종목상세 / 정보 | I28: =COUNTIFS('기능정의 상세'!$A$4:$A$1200,A28,'기능정의 상세'!$K$4:$K$1200,"<>삭제") -> 7 | J28: 초안 | K28: 명칭변경 | L28: 거래 / 전체 / 종목상세 / 정보 | M28: 2Depth '전체' → '종목' (S023 명칭 변경에 따라 경로 자동 반영)
A29: S025 | B29: 거래 | C29: 종목 | D29: 종목상세 | E29: 정보> 예상분배금 계산기 | F29: 바텀시트 | G29: =B29&IF(OR(C29="",C29="—"),"", " / "&C29)&IF(OR(D29="",D29="—"),"", " / "&D29)&IF(OR(E29="",E29="—"),"", " / "&E29) -> 거래 / 종목 / 종목상세 / 정보> 예상분배금 계산기 | I29: =COUNTIFS('기능정의 상세'!$A$4:$A$1200,A29,'기능정의 상세'!$K$4:$K$1200,"<>삭제") -> 6 | J29: 초안 | K29: 수정 | L29: 거래 / 전체 / 종목상세 / 정보 > 예상분배금 계산기 | (화면구분) 상세 → 바텀시트 | M29: 화면구분 표기 통일: 계산기 = 바텀시트(R-01) | O29: 화면구분 추정
A30: S026 | B30: 거래 | C30: 종목 | D30: 종목상세 | E30: 정보> 발행공시 목록 | F30: 목록 | G30: =B30&IF(OR(C30="",C30="—"),"", " / "&C30)&IF(OR(D30="",D30="—"),"", " / "&D30)&IF(OR(E30="",E30="—"),"", " / "&E30) -> 거래 / 종목 / 종목상세 / 정보> 발행공시 목록 | I30: =COUNTIFS('기능정의 상세'!$A$4:$A$1200,A30,'기능정의 상세'!$K$4:$K$1200,"<>삭제") -> 4 | J30: 초안 | K30: 수정 | L30: 거래 / 전체 / 종목상세 / 정보 > 발행공시 목록 | M30: 헤더 제목 '공시' 표시 · 상세 이동을 오버레이 → 페이지로 변경(R-01)
A31: S027 | B31: 거래 | C31: 종목 | D31: 종목상세 | E31: 정보> 발행공시 상세 | F31: 상세 | G31: =B31&IF(OR(C31="",C31="—"),"", " / "&C31)&IF(OR(D31="",D31="—"),"", " / "&D31)&IF(OR(E31="",E31="—"),"", " / "&E31) -> 거래 / 종목 / 종목상세 / 정보> 발행공시 상세 | I31: =COUNTIFS('기능정의 상세'!$A$4:$A$1200,A31,'기능정의 상세'!$K$4:$K$1200,"<>삭제") -> 4 | J31: 초안 | K31: 수정 | L31: 거래 / 전체 / 종목상세 / 정보 > 발행공시 상세 | M31: 상세를 오버레이 → 전체 페이지로 변경 · 닫기(X) → 뒤로가기(←)(R-01)
A32: S028 | B32: 거래 | C32: 종목 | D32: 종목상세 | E32: 정보> 유통공시 목록 | F32: 목록 | G32: =B32&IF(OR(C32="",C32="—"),"", " / "&C32)&IF(OR(D32="",D32="—"),"", " / "&D32)&IF(OR(E32="",E32="—"),"", " / "&E32) -> 거래 / 종목 / 종목상세 / 정보> 유통공시 목록 | I32: =COUNTIFS('기능정의 상세'!$A$4:$A$1200,A32,'기능정의 상세'!$K$4:$K$1200,"<>삭제") -> 5 | J32: 초안 | K32: 수정 | L32: 거래 / 전체 / 종목상세 / 정보 > 유통공시 목록 | M32: 헤더 제목 '공시' 표시 · 상세 이동을 오버레이 → 페이지로 변경(R-01)
A33: S029 | B33: 거래 | C33: 종목 | D33: 종목상세 | E33: 정보> 유통공시 상세 | F33: 상세 | G33: =B33&IF(OR(C33="",C33="—"),"", " / "&C33)&IF(OR(D33="",D33="—"),"", " / "&D33)&IF(OR(E33="",E33="—"),"", " / "&E33) -> 거래 / 종목 / 종목상세 / 정보> 유통공시 상세 | I33: =COUNTIFS('기능정의 상세'!$A$4:$A$1200,A33,'기능정의 상세'!$K$4:$K$1200,"<>삭제") -> 5 | J33: 초안 | K33: 수정 | L33: 거래 / 전체 / 종목상세 / 정보 > 유통공시 상세 | M33: 상세를 오버레이 → 전체 페이지로 변경 · 닫기(X) → 뒤로가기(←)(R-01)
A34: S030 | B34: 거래 | C34: 종목 | D34: 종목상세 | E34: 주문 (간편) | F34: 탭(상세) | G34: =B34&IF(OR(C34="",C34="—"),"", " / "&C34)&IF(OR(D34="",D34="—"),"", " / "&D34)&IF(OR(E34="",E34="—"),"", " / "&E34) -> 거래 / 종목 / 종목상세 / 주문 (간편) | H34: Y | I34: =COUNTIFS('기능정의 상세'!$A$4:$A$1200,A34,'기능정의 상세'!$K$4:$K$1200,"<>삭제") -> 7 | J34: 초안 | K34: 수정 | L34: 거래 / 전체 / 종목상세 / 주문 (간편) | M34: 2Depth '전체' → '종목' (S023 명칭 변경에 따라 경로 자동 반영) · 본문 표기 통일('팝업' → '바텀시트', R-01) | N34: 아이콘 대체 예정. 텍스트 레이블 변경 없음
A35: S031 | B35: 거래 | C35: 종목 | D35: 종목상세 | E35: 주문 (간편)> 구매> 구매 희망가 | F35: 탭(상세) | G35: =B35&IF(OR(C35="",C35="—"),"", " / "&C35)&IF(OR(D35="",D35="—"),"", " / "&D35)&IF(OR(E35="",E35="—"),"", " / "&E35) -> 거래 / 종목 / 종목상세 / 주문 (간편)> 구매> 구매 희망가 | I35: =COUNTIFS('기능정의 상세'!$A$4:$A$1200,A35,'기능정의 상세'!$K$4:$K$1200,"<>삭제") -> 4 | J35: 초안 | K35: 수정 | L35: 거래 / 전체 / 종목상세 / 주문 (간편)> 구매> 구매 희망가 | M35: 2Depth '전체' → '종목' (S023 명칭 변경에 따라 경로 자동 반영) · 본문 표기 통일('팝업' → '바텀시트', R-01)
A36: S032 | B36: 거래 | C36: 종목 | D36: 종목상세 | E36: 주문 (간편)> 구매> 구매 희망가> 구매주문 | F36: 바텀시트 | G36: =B36&IF(OR(C36="",C36="—"),"", " / "&C36)&IF(OR(D36="",D36="—"),"", " / "&D36)&IF(OR(E36="",E36="—"),"", " / "&E36) -> 거래 / 종목 / 종목상세 / 주문 (간편)> 구매> 구매 희망가> 구매주문 | I36: =COUNTIFS('기능정의 상세'!$A$4:$A$1200,A36,'기능정의 상세'!$K$4:$K$1200,"<>삭제") -> 3 | J36: 초안 | K36: 수정 | L36: 거래 / 전체 / 종목상세 / 주문 (간편)> 구매> 구매 희망가> 구매주문 | (화면구분) 팝업 → 바텀시트 | M36: 주문 확인: 팝업 → 바텀시트(R-01)
A37: S033 | B37: 거래 | C37: 종목 | D37: 종목상세 | E37: 주문 (간편)> 구매> 구매 희망가> 구매완료 | F37: 상세 | G37: =B37&IF(OR(C37="",C37="—"),"", " / "&C37)&IF(OR(D37="",D37="—"),"", " / "&D37)&IF(OR(E37="",E37="—"),"", " / "&E37) -> 거래 / 종목 / 종목상세 / 주문 (간편)> 구매> 구매 희망가> 구매완료 | I37: =COUNTIFS('기능정의 상세'!$A$4:$A$1200,A37,'기능정의 상세'!$K$4:$K$1200,"<>삭제") -> 3 | J37: 초안 | K37: 수정 | L37: 거래 / 전체 / 종목상세 / 주문 (간편)> 구매> 구매 희망가> 구매완료 | (화면구분) 팝업 → 상세 | M37: 주문 완료: 팝업 → 전체 페이지(결과 화면). 일반 주문 완료와 동일 형식(R-01)
A38: S034 | B38: 거래 | C38: 종목 | D38: 종목상세 | E38: 주문 (간편)> 구매> AI매칭 | F38: 탭(상세) | G38: =B38&IF(OR(C38="",C38="—"),"", " / "&C38)&IF(OR(D38="",D38="—"),"", " / "&D38)&IF(OR(E38="",E38="—"),"", " / "&E38) -> 거래 / 종목 / 종목상세 / 주문 (간편)> 구매> AI매칭 | I38: =COUNTIFS('기능정의 상세'!$A$4:$A$1200,A38,'기능정의 상세'!$K$4:$K$1200,"<>삭제") -> 4 | J38: 초안 | K38: 수정 | L38: 거래 / 전체 / 종목상세 / 주문 (간편)> 구매> AI매칭 | M38: AI매칭 '주문예정내역' → '예상 체결 내역' 상시 노출 영역으로 변경(R-06)
A39: S035 | B39: 거래 | C39: 종목 | D39: 종목상세 | E39: 주문 (간편)> 구매> AI매칭> 구매주문 | F39: 바텀시트 | G39: =B39&IF(OR(C39="",C39="—"),"", " / "&C39)&IF(OR(D39="",D39="—"),"", " / "&D39)&IF(OR(E39="",E39="—"),"", " / "&E39) -> 거래 / 종목 / 종목상세 / 주문 (간편)> 구매> AI매칭> 구매주문 | I39: =COUNTIFS('기능정의 상세'!$A$4:$A$1200,A39,'기능정의 상세'!$K$4:$K$1200,"<>삭제") -> 5 | J39: 초안 | K39: 수정 | L39: 거래 / 전체 / 종목상세 / 주문 (간편)> 구매> AI매칭> 구매주문 | (화면구분) 팝업 → 바텀시트 | M39: 주문 확인: 팝업 → 바텀시트(R-01)
A40: S036 | B40: 거래 | C40: 종목 | D40: 종목상세 | E40: 주문 (간편)> 구매> AI매칭> 구매완료 | F40: 상세 | G40: =B40&IF(OR(C40="",C40="—"),"", " / "&C40)&IF(OR(D40="",D40="—"),"", " / "&D40)&IF(OR(E40="",E40="—"),"", " / "&E40) -> 거래 / 종목 / 종목상세 / 주문 (간편)> 구매> AI매칭> 구매완료 | I40: =COUNTIFS('기능정의 상세'!$A$4:$A$1200,A40,'기능정의 상세'!$K$4:$K$1200,"<>삭제") -> 4 | J40: 초안 | K40: 수정 | L40: 거래 / 전체 / 종목상세 / 주문 (간편)> 구매> AI매칭> 구매완료 | (화면구분) 팝업 → 상세 | M40: 주문 완료: 팝업 → 전체 페이지(결과 화면). 일반 주문 완료와 동일 형식(R-01)
A41: S037 | B41: 거래 | C41: 종목 | D41: 종목상세 | E41: 주문 (간편)> 판매> 판매 희망가 | F41: 탭(상세) | G41: =B41&IF(OR(C41="",C41="—"),"", " / "&C41)&IF(OR(D41="",D41="—"),"", " / "&D41)&IF(OR(E41="",E41="—"),"", " / "&E41) -> 거래 / 종목 / 종목상세 / 주문 (간편)> 판매> 판매 희망가 | I41: =COUNTIFS('기능정의 상세'!$A$4:$A$1200,A41,'기능정의 상세'!$K$4:$K$1200,"<>삭제") -> 4 | J41: 초안 | K41: 수정 | L41: 거래 / 전체 / 종목상세 / 주문 (간편)> 판매> 판매 희망가 | M41: 2Depth '전체' → '종목' (S023 명칭 변경에 따라 경로 자동 반영) · 본문 표기 통일('팝업' → '바텀시트', R-01)
...

Sheet 기능정의 상세
A1: 메뉴별 상세 기능정의 v2
A2: 파란 헤더(B~F열)는 '메뉴구조' 시트에서 화면ID로 자동 연동되는 값입니다(직접 수정 금지). 화면 추가 시 A열에 화면ID만 입력하세요.
A3: 화면ID | B3: 1Depth | C3: 2Depth | D3: 3Depth | E3: 4Depth | F3: 화면(전체 경로) | G3: 기능# | H3: 기능 제목 | I3: 설명 | J3: 정책/주의사항 | K3: 변경구분 | L3: 변경 내용 | M3: 변경 전 설명
A4: S001 | B4: =INDEX(메뉴구조!$B$5:$B$300,MATCH($A4,메뉴구조!$A$5:$A$300,0))&"" -> 스플래시 | C4: =INDEX(메뉴구조!$C$5:$C$300,MATCH($A4,메뉴구조!$A$5:$A$300,0))&"" -> — | D4: =INDEX(메뉴구조!$D$5:$D$300,MATCH($A4,메뉴구조!$A$5:$A$300,0))&"" -> — | E4: =INDEX(메뉴구조!$E$5:$E$300,MATCH($A4,메뉴구조!$A$5:$A$300,0))&"" -> — | F4: =INDEX(메뉴구조!$G$5:$G$300,MATCH($A4,메뉴구조!$A$5:$A$300,0))&"" -> 스플래시 | G4: 1 | H4: 서비스 로고 (한국ST거래) | I4: - 앱 브랜드 로고와 서비스명 '한국ST거래'가 상단에 표시됨 - 스플래시 화면 내 정적 요소로 별도의 클릭/탭 인터랙션은 감지되지 않음 - 화면에서 감지된 링크/버튼 목록이 제공되지 않아 실제 이동 대상은 확인되지 않음 | K4: 유지
A5: S001 | B5: =INDEX(메뉴구조!$B$5:$B$300,MATCH($A5,메뉴구조!$A$5:$A$300,0))&"" -> 스플래시 | C5: =INDEX(메뉴구조!$C$5:$C$300,MATCH($A5,메뉴구조!$A$5:$A$300,0))&"" -> — | D5: =INDEX(메뉴구조!$D$5:$D$300,MATCH($A5,메뉴구조!$A$5:$A$300,0))&"" -> — | E5: =INDEX(메뉴구조!$E$5:$E$300,MATCH($A5,메뉴구조!$A$5:$A$300,0))&"" -> — | F5: =INDEX(메뉴구조!$G$5:$G$300,MATCH($A5,메뉴구조!$A$5:$A$300,0))&"" -> 스플래시 | G5: 2 | H5: 메인 슬로건 문구 | I5: - '당신의 일상이 가치가 되는 곳'이라는 브랜드 슬로건 텍스트 - 서비스의 정체성(투자계약증권 다자간상대매매 유통 앱)을 함축적으로 전달하는 문구로 추정됨 - 별도의 사용자 액션(입력/클릭)은 없는 순수 텍스트 요소 | K5: 유지
A6: S001 | B6: =INDEX(메뉴구조!$B$5:$B$300,MATCH($A6,메뉴구조!$A$5:$A$300,0))&"" -> 스플래시 | C6: =INDEX(메뉴구조!$C$5:$C$300,MATCH($A6,메뉴구조!$A$5:$A$300,0))&"" -> — | D6: =INDEX(메뉴구조!$D$5:$D$300,MATCH($A6,메뉴구조!$A$5:$A$300,0))&"" -> — | E6: =INDEX(메뉴구조!$E$5:$E$300,MATCH($A6,메뉴구조!$A$5:$A$300,0))&"" -> — | F6: =INDEX(메뉴구조!$G$5:$G$300,MATCH($A6,메뉴구조!$A$5:$A$300,0))&"" -> 스플래시 | G6: 3 | H6: 일러스트레이션 (상점가 이미지) | I6: - 카페, 레스토랑, 뷰티샵, 마트 등 다양한 업종의 상점이 나란히 배치된 아이소메트릭 스타일 일러스트 - 하단에 디지털/네트워크 느낌의 발광 그래픽이 배치되어 '오프라인 가게'가 '디지털 자산(증권)'으로 연결됨을 상징적으로 표현한 것으로 추정됨 (약관상 '가게'·'종목' 개념과 연관 추정) - 클릭/탭 등 인터랙션 요소로 보이지 않음 | K6: 유지
A7: S001 | B7: =INDEX(메뉴구조!$B$5:$B$300,MATCH($A7,메뉴구조!$A$5:$A$300,0))&"" -> 스플래시 | C7: =INDEX(메뉴구조!$C$5:$C$300,MATCH($A7,메뉴구조!$A$5:$A$300,0))&"" -> — | D7: =INDEX(메뉴구조!$D$5:$D$300,MATCH($A7,메뉴구조!$A$5:$A$300,0))&"" -> — | E7: =INDEX(메뉴구조!$E$5:$E$300,MATCH($A7,메뉴구조!$A$5:$A$300,0))&"" -> — | F7: =INDEX(메뉴구조!$G$5:$G$300,MATCH($A7,메뉴구조!$A$5:$A$300,0))&"" -> 스플래시 | G7: 4 | H7: 로딩 진행률 표시 (%) | I7: - 현재 로딩 진행률을 숫자(%)로 표시 (캡처 시점 59%) - 앱 초기 구동 시 리소스/데이터 로딩 진행 상태를 실시간으로 갱신하여 보여주는 요소로 추정됨 - 100% 도달 시 다음 화면(로그인 또는 메인)으로 자동 전환될 것으로 추정되나, 실제 전환 대상 화면은 이 캡처만으로는 확인 불가 | K7: 유지
A8: S001 | B8: =INDEX(메뉴구조!$B$5:$B$300,MATCH($A8,메뉴구조!$A$5:$A$300,0))&"" -> 스플래시 | C8: =INDEX(메뉴구조!$C$5:$C$300,MATCH($A8,메뉴구조!$A$5:$A$300,0))&"" -> — | D8: =INDEX(메뉴구조!$D$5:$D$300,MATCH($A8,메뉴구조!$A$5:$A$300,0))&"" -> — | E8: =INDEX(메뉴구조!$E$5:$E$300,MATCH($A8,메뉴구조!$A$5:$A$300,0))&"" -> — | F8: =INDEX(메뉴구조!$G$5:$G$300,MATCH($A8,메뉴구조!$A$5:$A$300,0))&"" -> 스플래시 | G8: 5 | H8: 로딩 프로그레스 바 | I8: - 위 진행률(%)에 대응하여 채워지는 가로형 진행 바 - 사용자 조작이 불가능한 상태 표시 전용 요소 - 로딩 완료 전까지 다른 화면으로의 진입(뒤로가기 등)이 제한될 가능성이 있으나 이 화면만으로는 확인 불가 | K8: 유지
A9: S001 | B9: =INDEX(메뉴구조!$B$5:$B$300,MATCH($A9,메뉴구조!$A$5:$A$300,0))&"" -> 스플래시 | C9: =INDEX(메뉴구조!$C$5:$C$300,MATCH($A9,메뉴구조!$A$5:$A$300,0))&"" -> — | D9: =INDEX(메뉴구조!$D$5:$D$300,MATCH($A9,메뉴구조!$A$5:$A$300,0))&"" -> — | E9: =INDEX(메뉴구조!$E$5:$E$300,MATCH($A9,메뉴구조!$A$5:$A$300,0))&"" -> — | F9: =INDEX(메뉴구조!$G$5:$G$300,MATCH($A9,메뉴구조!$A$5:$A$300,0))&"" -> 스플래시 | G9: 6 | H9: 로딩 안내 문구 | I9: - '최신 정보로 업데이트 중입니다.' 안내 텍스트 - 앱 실행 시 최신 시세/종목/공지 등 데이터를 서버에서 갱신하는 동안 사용자에게 대기를 안내하는 문구로 추정됨 - 로딩 실패(네트워크 오류 등) 시의 예외 처리 UI는 이 캡처에서 확인되지 않음 | K9: 유지
A10: S002 | B10: =INDEX(메뉴구조!$B$5:$B$300,MATCH($A10,메뉴구조!$A$5:$A$300,0))&"" -> 회원가입 | C10: =INDEX(메뉴구조!$C$5:$C$300,MATCH($A10,메뉴구조!$A$5:$A$300,0))&"" -> 약관동의 | D10: =INDEX(메뉴구조!$D$5:$D$300,MATCH($A10,메뉴구조!$A$5:$A$300,0))&"" -> — | E10: =INDEX(메뉴구조!$E$5:$E$300,MATCH($A10,메뉴구조!$A$5:$A$300,0))&"" -> — | F10: =INDEX(메뉴구조!$G$5:$G$300,MATCH($A10,메뉴구조!$A$5:$A$300,0))&"" -> 회원가입 / 약관동의 | G10: 1 | H10: 진행 단계 표시 | I10: - 화면 좌측 상단에 뒤로가기 버튼, 우측에 전체 3단계 중 현재 단계를 'N / 03' 형식으로 표시 - 그 아래 진행 바(주황색)가 현재 단계만큼 채워진다 - 회원가입은 약관동의(01) → 본인인증(02) → 회원정보 입력 등으로 이어지는 멀티스텝 폼이며, 뒤로가기를 누르면 이전 단계(첫 단계에서는 가입 진입 전 화면)로 돌아간다 | K10: 유지
A11: S002 | B11: =INDEX(메뉴구조!$B$5:$B$300,MATCH($A11,메뉴구조!$A$5:$A$300,0))&"" -> 회원가입 | C11: =INDEX(메뉴구조!$C$5:$C$300,MATCH($A11,메뉴구조!$A$5:$A$300,0))&"" -> 약관동의 | D11: =INDEX(메뉴구조!$D$5:$D$300,MATCH($A11,메뉴구조!$A$5:$A$300,0))&"" -> — | E11: =INDEX(메뉴구조!$E$5:$E$300,MATCH($A11,메뉴구조!$A$5:$A$300,0))&"" -> — | F11: =INDEX(메뉴구조!$G$5:$G$300,MATCH($A11,메뉴구조!$A$5:$A$300,0))&"" -> 회원가입 / 약관동의 | G11: 2 | H11: 안내 타이틀 | I11: '서비스 이용을 위한 약관에 동의해 주세요.' 2줄 안내 문구. 이 화면의 목적(약관 동의)을 굵은 글씨로 바로 인지시킨다. | K11: 유지
A12: S002 | B12: =INDEX(메뉴구조!$B$5:$B$300,MATCH($A12,메뉴구조!$A$5:$A$300,0))&"" -> 회원가입 | C12: =INDEX(메뉴구조!$C$5:$C$300,MATCH($A12,메뉴구조!$A$5:$A$300,0))&"" -> 약관동의 | D12: =INDEX(메뉴구조!$D$5:$D$300,MATCH($A12,메뉴구조!$A$5:$A$300,0))&"" -> — | E12: =INDEX(메뉴구조!$E$5:$E$300,MATCH($A12,메뉴구조!$A$5:$A$300,0))&"" -> — | F12: =INDEX(메뉴구조!$G$5:$G$300,MATCH($A12,메뉴구조!$A$5:$A$300,0))&"" -> 회원가입 / 약관동의 | G12: 3 | H12: [필수] 전체동의 토글 | I12: - 좌측 체크박스 + 우측 펼침/접힘 화살표(v)로 구성된 아코디언 헤더 - 체크하면 하위 4개 약관이 모두 체크되고, 화살표를 누르면 하위 항목 목록이 펼쳐지거나 접힌다(캡처는 펼쳐진 상태) - '[필수]' 라벨대로 이 전체동의(=하위 4개 모두 동의)가 완료돼야 다음 단계로 진행할 수 있다 | J12: 이용약관 제4조②: '서비스에 가입하려는 사람은 본 약관에 동의하고, 회사가 요구하는 본인인증 절차를 완료하여야 한다' — 이 화면이 그 시작 지점이다. | K12: 유지
A13: S002 | B13: =INDEX(메뉴구조!$B$5:$B$300,MATCH($A13,메뉴구조!$A$5:$A$300,0))&"" -> 회원가입 | C13: =INDEX(메뉴구조!$C$5:$C$300,MATCH($A13,메뉴구조!$A$5:$A$300,0))&"" -> 약관동의 | D13: =INDEX(메뉴구조!$D$5:$D$300,MATCH($A13,메뉴구조!$A$5:$A$300,0))&"" -> — | E13: =INDEX(메뉴구조!$E$5:$E$300,MATCH($A13,메뉴구조!$A$5:$A$300,0))&"" -> — | F13: =INDEX(메뉴구조!$G$5:$G$300,MATCH($A13,메뉴구조!$A$5:$A$300,0))&"" -> 회원가입 / 약관동의 | G13: 4 | H13: 개별 약관 체크리스트 (4개) | I13: - [필수] 개인정보 수집·이용 동의 / [필수] 통신사 이용 약관 / [필수] 서비스 이용약관 / [필수] 투자자 유의사항, 총 4행 - 각 행은 체크박스 + 우측 '>' 화살표로 구성되며, 화살표(또는 문구)를 누르면 해당 약관 전문이 뜨는 화면/바텀시트로 이동할 것으로 추정(현재 캡처만으로 상세 진입 UI는 확인 불가 — 실기기 검증 필요) - 4개 모두 체크돼야 전체동의가 활성화되고 [다음] 버튼도 활성화된다 | J13: '서비스 이용약관' 항목은 실제 이용약관 전문(제1~21조)과, '투자자 유의사항'은 AI매칭 비권유·수익률 참고용 등 투자자 보호 고지사항과 정확히 연결되는지 QA 필요. | K13: 유지
A14: S002 | B14: =INDEX(메뉴구조!$B$5:$B$300,MATCH($A14,메뉴구조!$A$5:$A$300,0))&"" -> 회원가입 | C14: =INDEX(메뉴구조!$C$5:$C$300,MATCH($A14,메뉴구조!$A$5:$A$300,0))&"" -> 약관동의 | D14: =INDEX(메뉴구조!$D$5:$D$300,MATCH($A14,메뉴구조!$A$5:$A$300,0))&"" -> — | E14: =INDEX(메뉴구조!$E$5:$E$300,MATCH($A14,메뉴구조!$A$5:$A$300,0))&"" -> — | F14: =INDEX(메뉴구조!$G$5:$G$300,MATCH($A14,메뉴구조!$A$5:$A$300,0))&"" -> 회원가입 / 약관동의 | G14: 5 | H14: 하단 [다음] 버튼 | I14: - 화면 하단 고정 버튼 - 캡처 시점(전부 미체크)에는 비활성(회색)으로 보인다 - 필수 약관 4개가 모두 체크돼야 활성화되며, 누르면 다음 단계(02/03, 본인인증)로 이동할 것으로 추정된다 - 일부만 체크한 상태에서의 동작(비활성으로 클릭 자체가 막히는지, 클릭 시 안내 토스트가 뜨는지)은 실기기 확인 필요 | K14: 유지
A15: S003 | B15: =INDEX(메뉴구조!$B$5:$B$300,MATCH($A15,메뉴구조!$A$5:$A$300,0))&"" -> 회원가입 | C15: =INDEX(메뉴구조!$C$5:$C$300,MATCH($A15,메뉴구조!$A$5:$A$300,0))&"" -> 본인인증_정책 | D15: =INDEX(메뉴구조!$D$5:$D$300,MATCH($A15,메뉴구조!$A$5:$A$300,0))&"" -> — | E15: =INDEX(메뉴구조!$E$5:$E$300,MATCH($A15,메뉴구조!$A$5:$A$300,0))&"" -> — | F15: =INDEX(메뉴구조!$G$5:$G$300,MATCH($A15,메뉴구조!$A$5:$A$300,0))&"" -> 회원가입 / 본인인증_정책 | G15: 1 | H15: 본인인증 실패 안내 아이콘 | I15: - 경고(⚠) 표시가 있는 노트북 일러스트로, 본인인증 절차 중 오류가 발생했음을 시각적으로 알림 - 별도의 클릭/탭 동작 없는 순수 안내용 이미지 | K15: 유지
A16: S003 | B16: =INDEX(메뉴구조!$B$5:$B$300,MATCH($A16,메뉴구조!$A$5:$A$300,0))&"" -> 회원가입 | C16: =INDEX(메뉴구조!$C$5:$C$300,MATCH($A16,메뉴구조!$A$5:$A$300,0))&"" -> 본인인증_정책 | D16: =INDEX(메뉴구조!$D$5:$D$300,MATCH($A16,메뉴구조!$A$5:$A$300,0))&"" -> — | E16: =INDEX(메뉴구조!$E$5:$E$300,MATCH($A16,메뉴구조!$A$5:$A$300,0))&"" -> — | F16: =INDEX(메뉴구조!$G$5:$G$300,MATCH($A16,메뉴구조!$A$5:$A$300,0))&"" -> 회원가입 / 본인인증_정책 | G16: 2 | H16: 실패 안내 타이틀 | I16: - "본인인증에 실패했습니다." 굵은 글씨의 메인 안내 문구 - 회원가입 절차 중 본인인증(실명인증·휴대폰 인증 등) 처리 과정에서 오류가 발생했을 때 노출되는 전체화면 에러 상태로 추정됨 | K16: 유지
A17: S003 | B17: =INDEX(메뉴구조!$B$5:$B$300,MATCH($A17,메뉴구조!$A$5:$A$300,0))&"" -> 회원가입 | C17: =INDEX(메뉴구조!$C$5:$C$300,MATCH($A17,메뉴구조!$A$5:$A$300,0))&"" -> 본인인증_정책 | D17: =INDEX(메뉴구조!$D$5:$D$300,MATCH($A17,메뉴구조!$A$5:$A$300,0))&"" -> — | E17: =INDEX(메뉴구조!$E$5:$E$300,MATCH($A17,메뉴구조!$A$5:$A$300,0))&"" -> — | F17: =INDEX(메뉴구조!$G$5:$G$300,MATCH($A17,메뉴구조!$A$5:$A$300,0))&"" -> 회원가입 / 본인인증_정책 | G17: 3 | H17: 실패 사유 및 재시도 안내 문구 | I17: - "본인인증 중 오류가 발생했습니다." / "잠시 후 다시 시도해 주세요." 2줄의 보조 설명 텍스트 - 구체적인 실패 사유(통신사 인증 실패, 타임아웃 등)를 구분하지 않고 공통 안내 문구만 노출되는 것으로 보임 - 사용자에게 즉시 재시도를 유도하는 문구 | K17: 유지
A18: S003 | B18: =INDEX(메뉴구조!$B$5:$B$300,MATCH($A18,메뉴구조!$A$5:$A$300,0))&"" -> 회원가입 | C18: =INDEX(메뉴구조!$C$5:$C$300,MATCH($A18,메뉴구조!$A$5:$A$300,0))&"" -> 본인인증_정책 | D18: =INDEX(메뉴구조!$D$5:$D$300,MATCH($A18,메뉴구조!$A$5:$A$300,0))&"" -> — | E18: =INDEX(메뉴구조!$E$5:$E$300,MATCH($A18,메뉴구조!$A$5:$A$300,0))&"" -> — | F18: =INDEX(메뉴구조!$G$5:$G$300,MATCH($A18,메뉴구조!$A$5:$A$300,0))&"" -> 회원가입 / 본인인증_정책 | G18: 4 | H18: 확인 버튼 | I18: - 화면 하단 고정된 짙은 남색 배경의 전체 폭 버튼 - 감지된 href/이동 대상 정보가 없어 정확한 이동 경로는 확정할 수 없음 - 일반적인 에러 화면의 '확인' 버튼 패턴을 고려하면, 탭 시 이전 본인인증 입력 화면(또는 회원가입 시작 화면)으로 돌아가 재시도할 수 있도록 하는 동작으로 추정됨 (확정 아님) - 별도 유효성검사 없이 단순 확인/닫기 액션으로 추정 | K18: 유지
A19: S005 | B19: =INDEX(메뉴구조!$B$5:$B$300,MATCH($A19,메뉴구조!$A$5:$A$300,0))&"" -> 회원가입 | C19: =INDEX(메뉴구조!$C$5:$C$300,MATCH($A19,메뉴구조!$A$5:$A$300,0))&"" -> 로그인설정 (생체) | D19: =INDEX(메뉴구조!$D$5:$D$300,MATCH($A19,메뉴구조!$A$5:$A$300,0))&"" -> — | E19: =INDEX(메뉴구조!$E$5:$E$300,MATCH($A19,메뉴구조!$A$5:$A$300,0))&"" -> — | F19: =INDEX(메뉴구조!$G$5:$G$300,MATCH($A19,메뉴구조!$A$5:$A$300,0))&"" -> 회원가입 / 로그인설정 (생체) | G19: 1 | H19: 간편 인증으로 로그인 설정 카드 | I19: - PIN 아이콘(****)과 '간편 인증으로 로그인' 텍스트가 표시된 선택형 카드 - 회원가입/로그인설정(생체) 화면 문맥상 간편 비밀번호(PIN) 또는 생체인증(지문·안면) 등록을 시작하는 진입 요소로 추정됨(화면에서 감지된 링크/버튼 목록이 제공되지 않아 실제 이동 대상은 스크린샷만으로 단정할 수 없음) - 탭 시 기기에 등록된 생체정보 인식 또는 PIN 입력 화면으로 이어지는 것으로 보이며, 설정 완료 후 하단 [확인] 버튼이 활성화될 가능성이 있음 - 카드가 선택/미선택 토글 형태인지, 탭 즉시 별도 화면으로 이동하는 링크형인지는 스크린샷만으로 확정할 수 없음 | J19: 약관 제5조④에 따르면 간편인증(PIN·생체인증) 설정을 위해서는 별도의 본인인증 완료 후 신규 기기 등록 절차가 필요할 수 있음 | K19: 유지
A20: S005 | B20: =INDEX(메뉴구조!$B$5:$B$300,MATCH($A20,메뉴구조!$A$5:$A$300,0))&"" -> 회원가입 | C20: =INDEX(메뉴구조!$C$5:$C$300,MATCH($A20,메뉴구조!$A$5:$A$300,0))&"" -> 로그인설정 (생체) | D20: =INDEX(메뉴구조!$D$5:$D$300,MATCH($A20,메뉴구조!$A$5:$A$300,0))&"" -> — | E20: =INDEX(메뉴구조!$E$5:$E$300,MATCH($A20,메뉴구조!$A$5:$A$300,0))&"" -> — | F20: =INDEX(메뉴구조!$G$5:$G$300,MATCH($A20,메뉴구조!$A$5:$A$300,0))&"" -> 회원가입 / 로그인설정 (생체) | G20: 2 | H20: 안내 타이틀 문구 | I20: - '로그인, 더 쉽게 할 수 있어요.' / '간편 로그인 방식을 설정해주세요.' 2줄 굵은 텍스트 - 화면의 목적(간편 로그인 방식 설정)을 안내하는 순수 정보성 텍스트로, 클릭 동작 없음 | K20: 유지
A21: S005 | B21: =INDEX(메뉴구조!$B$5:$B$300,MATCH($A21,메뉴구조!$A$5:$A$300,0))&"" -> 회원가입 | C21: =INDEX(메뉴구조!$C$5:$C$300,MATCH($A21,메뉴구조!$A$5:$A$300,0))&"" -> 로그인설정 (생체) | D21: =INDEX(메뉴구조!$D$5:$D$300,MATCH($A21,메뉴구조!$A$5:$A$300,0))&"" -> — | E21: =INDEX(메뉴구조!$E$5:$E$300,MATCH($A21,메뉴구조!$A$5:$A$300,0))&"" -> — | F21: =INDEX(메뉴구조!$G$5:$G$300,MATCH($A21,메뉴구조!$A$5:$A$300,0))&"" -> 회원가입 / 로그인설정 (생체) | G21: 3 | H21: 확인 버튼 | I21: - 화면 하단 우측에 위치한 주요 액션 버튼 - 탭 시 위에서 설정한 간편 인증(생체인증/PIN) 방식을 저장하고 다음 화면(가입 완료 또는 로그인 흐름)으로 진행하는 것으로 추정됨 - 간편 인증 카드가 아직 설정되지 않은 초기 상태에서는 비활성(회색) 상태일 수 있으며, 설정 완료 시 활성화되는 형태로 보임(실제 활성화 조건은 스크린샷만으로 단정 불가) - 필수 항목 미입력/미설정 시 탭해도 진행되지 않고 안내 메시지가 표시될 가능성 있음 | K21: 유지
A22: S005 | B22: =INDEX(메뉴구조!$B$5:$B$300,MATCH($A22,메뉴구조!$A$5:$A$300,0))&"" -> 회원가입 | C22: =INDEX(메뉴구조!$C$5:$C$300,MATCH($A22,메뉴구조!$A$5:$A$300,0))&"" -> 로그인설정 (생체) | D22: =INDEX(메뉴구조!$D$5:$D$300,MATCH($A22,메뉴구조!$A$5:$A$300,0))&"" -> — | E22: =INDEX(메뉴구조!$E$5:$E$300,MATCH($A22,메뉴구조!$A$5:$A$300,0))&"" -> — | F22: =INDEX(메뉴구조!$G$5:$G$300,MATCH($A22,메뉴구조!$A$5:$A$300,0))&"" -> 회원가입 / 로그인설정 (생체) | G22: 4 | H22: 취소 버튼 | I22: - 화면 하단 좌측에 위치한 보조 액션 버튼 - 탭 시 간편 로그인 방식 설정을 취소하고 이전 화면(가입 절차 또는 로그인 화면)으로 돌아가는 것으로 추정됨 - 별도의 확인 팝업 없이 즉시 취소 처리되는지는 스크린샷만으로 확인 불가 | K22: 유지
A23: S005 | B23: =INDEX(메뉴구조!$B$5:$B$300,MATCH($A23,메뉴구조!$A$5:$A$300,0))&"" -> 회원가입 | C23: =INDEX(메뉴구조!$C$5:$C$300,MATCH($A23,메뉴구조!$A$5:$A$300,0))&"" -> 로그인설정 (생체) | D23: =INDEX(메뉴구조!$D$5:$D$300,MATCH($A23,메뉴구조!$A$5:$A$300,0))&"" -> — | E23: =INDEX(메뉴구조!$E$5:$E$300,MATCH($A23,메뉴구조!$A$5:$A$300,0))&"" -> — | F23: =INDEX(메뉴구조!$G$5:$G$300,MATCH($A23,메뉴구조!$A$5:$A$300,0))&"" -> 회원가입 / 로그인설정 (생체) | G23: 5 | H23: 뒤로가기 버튼 | I23: - 좌상단 화살표(←) 아이콘 - 탭 시 직전 화면(회원가입 절차의 이전 단계)으로 돌아가는 내비게이션 버튼으로 추정됨 - 입력/선택 중이던 간편 인증 설정 내용은 저장되지 않고 소실될 가능성 있음 | K23: 유지
A24: S005 | B24: =INDEX(메뉴구조!$B$5:$B$300,MATCH($A24,메뉴구조!$A$5:$A$300,0))&"" -> 회원가입 | C24: =INDEX(메뉴구조!$C$5:$C$300,MATCH($A24,메뉴구조!$A$5:$A$300,0))&"" -> 로그인설정 (생체) | D24: =INDEX(메뉴구조!$D$5:$D$300,MATCH($A24,메뉴구조!$A$5:$A$300,0))&"" -> — | E24: =INDEX(메뉴구조!$E$5:$E$300,MATCH($A24,메뉴구조!$A$5:$A$300,0))&"" -> — | F24: =INDEX(메뉴구조!$G$5:$G$300,MATCH($A24,메뉴구조!$A$5:$A$300,0))&"" -> 회원가입 / 로그인설정 (생체) | G24: 6 | H24: 간편 로그인 방식 변경 안내 문구 | I24: - '※ 로그인 방식은 마이 > 설정에서 언제든 바꿀 수 있어요.' 회색 보조 텍스트 - 현재 설정한 간편 로그인 방식이 이후 마이페이지 내 설정 메뉴에서 변경 가능함을 안내하는 정보성 텍스트 - 클릭 동작이 있는 링크형 텍스트인지, 단순 안내 문구인지는 스크린샷만으로 단정할 수 없음(밑줄 등 링크 스타일 없음 기준 단순 텍스트로 추정) | J24: 로그인 방식(간편 비밀번호/생체인증)은 마이 > 설정 메뉴에서 언제든 재변경 가능함을 명시 | K24: 유지
A25: S006 | B25: =INDEX(메뉴구조!$B$5:$B$300,MATCH($A25,메뉴구조!$A$5:$A$300,0))&"" -> 회원가입 | C25: =INDEX(메뉴구조!$C$5:$C$300,MATCH($A25,메뉴구조!$A$5:$A$300,0))&"" -> 투자정보 입력 | D25: =INDEX(메뉴구조!$D$5:$D$300,MATCH($A25,메뉴구조!$A$5:$A$300,0))&"" -> — | E25: =INDEX(메뉴구조!$E$5:$E$300,MATCH($A25,메뉴구조!$A$5:$A$300,0))&"" -> — | F25: =INDEX(메뉴구조!$G$5:$G$300,MATCH($A25,메뉴구조!$A$5:$A$300,0))&"" -> 회원가입 / 투자정보 입력 | G25: 1 | H25: 다음 버튼 (하단 CTA) | I25: - 화면 하단에 고정된 전체 폭 버튼 - 탭 시 회원가입 다음 단계(또는 가입 완료 처리)로 이동하는 것으로 추정 — 이동 대상 href 정보가 감지되지 않아 정확한 목적지는 스크린샷만으로 단정할 수 없음 - 버튼 색상이 연한 회색으로 표시되어 있어, 자금출처 등 필수 항목(*) 미입력 상태에서는 비활성 처리되는 것으로 추정 - 필수 항목을 모두 입력해야 다음 단계 진행이 가능할 것으로 보임 | K25: 유지
A26: S006 | B26: =INDEX(메뉴구조!$B$5:$B$300,MATCH($A26,메뉴구조!$A$5:$A$300,0))&"" -> 회원가입 | C26: =INDEX(메뉴구조!$C$5:$C$300,MATCH($A26,메뉴구조!$A$5:$A$300,0))&"" -> 투자정보 입력 | D26: =INDEX(메뉴구조!$D$5:$D$300,MATCH($A26,메뉴구조!$A$5:$A$300,0))&"" -> — | E26: =INDEX(메뉴구조!$E$5:$E$300,MATCH($A26,메뉴구조!$A$5:$A$300,0))&"" -> — | F26: =INDEX(메뉴구조!$G$5:$G$300,MATCH($A26,메뉴구조!$A$5:$A$300,0))&"" -> 회원가입 / 투자정보 입력 | G26: 2 | H26: 자금출처 선택 드롭다운 | I26: - "선택해 주세요." 플레이스홀더가 표시된 필수 입력 항목(* 표시), 우측 화살표 아이콘으로 드롭다운/바텀시트 트리거임을 나타냄 - 탭 시 자금출처 선택 옵션(예: 근로소득, 사업소득, 재산소득 등)이 노출되는 선택 UI로 추정 — 구체적 옵션 목록은 스크린샷만으로 확인 불가 - 현재 값이 비어 있어 미입력 상태이며, 필수값이므로 선택하지 않으면 하단 [다음] 진행이 제한되는 것으로 추정 | J26: 회원가입 시 수집되는 투자정보 항목으로, 약관상 증권사 계좌 연동 및 투자자 성향 분석(제8조)과 연계되는 기초 정보로 추정됨 | K26: 유지
A27: S006 | B27: =INDEX(메뉴구조!$B$5:$B$300,MATCH($A27,메뉴구조!$A$5:$A$300,0))&"" -> 회원가입 | C27: =INDEX(메뉴구조!$C$5:$C$300,MATCH($A27,메뉴구조!$A$5:$A$300,0))&"" -> 투자정보 입력 | D27: =INDEX(메뉴구조!$D$5:$D$300,MATCH($A27,메뉴구조!$A$5:$A$300,0))&"" -> — | E27: =INDEX(메뉴구조!$E$5:$E$300,MATCH($A27,메뉴구조!$A$5:$A$300,0))&"" -> — | F27: =INDEX(메뉴구조!$G$5:$G$300,MATCH($A27,메뉴구조!$A$5:$A$300,0))&"" -> 회원가입 / 투자정보 입력 | G27: 3 | H27: 투자목적 입력/선택 필드 | I27: - "저축 및 투자" 값이 이미 채워져 있는 필수 항목(* 표시) - 자금출처와 동일한 박스 스타일로, 텍스트 직접입력형인지 별도 선택형(드롭다운/바텀시트)인지는 스크린샷만으로 단정 불가하며 선택형일 가능성이 있음(추정) - 필수 항목이므로 값이 비어 있으면 [다음] 진행이 제한될 것으로 추정 | K27: 유지
A28: S006 | B28: =INDEX(메뉴구조!$B$5:$B$300,MATCH($A28,메뉴구조!$A$5:$A$300,0))&"" -> 회원가입 | C28: =INDEX(메뉴구조!$C$5:$C$300,MATCH($A28,메뉴구조!$A$5:$A$300,0))&"" -> 투자정보 입력 | D28: =INDEX(메뉴구조!$D$5:$D$300,MATCH($A28,메뉴구조!$A$5:$A$300,0))&"" -> — | E28: =INDEX(메뉴구조!$E$5:$E$300,MATCH($A28,메뉴구조!$A$5:$A$300,0))&"" -> — | F28: =INDEX(메뉴구조!$G$5:$G$300,MATCH($A28,메뉴구조!$A$5:$A$300,0))&"" -> 회원가입 / 투자정보 입력 | G28: 4 | H28: 직업 입력/선택 필드 | I28: - "직장인(회사원)" 값이 이미 채워져 있는 필수 항목(* 표시) - 위 두 항목과 동일한 UI 스타일로, 선택형 필드로 추정되며 정확한 입력 방식은 스크린샷만으로 확인 불가 - 필수 항목이므로 값이 비어 있으면 [다음] 진행이 제한될 것으로 추정 | K28: 유지
A29: S006 | B29: =INDEX(메뉴구조!$B$5:$B$300,MATCH($A29,메뉴구조!$A$5:$A$300,0))&"" -> 회원가입 | C29: =INDEX(메뉴구조!$C$5:$C$300,MATCH($A29,메뉴구조!$A$5:$A$300,0))&"" -> 투자정보 입력 | D29: =INDEX(메뉴구조!$D$5:$D$300,MATCH($A29,메뉴구조!$A$5:$A$300,0))&"" -> — | E29: =INDEX(메뉴구조!$E$5:$E$300,MATCH($A29,메뉴구조!$A$5:$A$300,0))&"" -> — | F29: =INDEX(메뉴구조!$G$5:$G$300,MATCH($A29,메뉴구조!$A$5:$A$300,0))&"" -> 회원가입 / 투자정보 입력 | G29: 5 | H29: 화면 안내 타이틀 | I29: - "투자를 위한 기본정보를 입력해주세요." 문구로, 본 화면이 회원가입 절차 중 투자정보(자금출처·투자목적·직업) 입력 단계임을 안내 - 순수 텍스트 요소로 별도의 클릭 동작은 없는 것으로 추정 | K29: 유지
A30: S006 | B30: =INDEX(메뉴구조!$B$5:$B$300,MATCH($A30,메뉴구조!$A$5:$A$300,0))&"" -> 회원가입 | C30: =INDEX(메뉴구조!$C$5:$C$300,MATCH($A30,메뉴구조!$A$5:$A$300,0))&"" -> 투자정보 입력 | D30: =INDEX(메뉴구조!$D$5:$D$300,MATCH($A30,메뉴구조!$A$5:$A$300,0))&"" -> — | E30: =INDEX(메뉴구조!$E$5:$E$300,MATCH($A30,메뉴구조!$A$5:$A$300,0))&"" -> — | F30: =INDEX(메뉴구조!$G$5:$G$300,MATCH($A30,메뉴구조!$A$5:$A$300,0))&"" -> 회원가입 / 투자정보 입력 | G30: 6 | H30: 진행 단계 표시 (03/03) | I30: - 회원가입 정보 입력 절차의 총 3단계 중 마지막 단계(3/3)임을 나타내는 텍스트 - 상단의 진행 바가 전체 채워진 상태로 표시되어 마지막 입력 단계임을 시각적으로 안내 - 순수 표시 요소로 클릭 동작 없음 | K30: 유지
A31: S006 | B31: =INDEX(메뉴구조!$B$5:$B$300,MATCH($A31,메뉴구조!$A$5:$A$300,0))&"" -> 회원가입 | C31: =INDEX(메뉴구조!$C$5:$C$300,MATCH($A31,메뉴구조!$A$5:$A$300,0))&"" -> 투자정보 입력 | D31: =INDEX(메뉴구조!$D$5:$D$300,MATCH($A31,메뉴구조!$A$5:$A$300,0))&"" -> — | E31: =INDEX(메뉴구조!$E$5:$E$300,MATCH($A31,메뉴구조!$A$5:$A$300,0))&"" -> — | F31: =INDEX(메뉴구조!$G$5:$G$300,MATCH($A31,메뉴구조!$A$5:$A$300,0))&"" -> 회원가입 / 투자정보 입력 | G31: 7 | H31: 뒤로가기 아이콘 | I31: - 좌상단 화살표 아이콘 - 탭 시 이전 입력 단계(02/03)로 이동하는 것으로 추정 — 이동 대상 href 정보가 감지되지 않아 정확한 동작은 화면 흐름상 추정치임 - 이전 단계로 돌아갈 때 현재 입력값 유지 여부는 스크린샷만으로 확인 불가 | K31: 유지
A32: S007 | B32: =INDEX(메뉴구조!$B$5:$B$300,MATCH($A32,메뉴구조!$A$5:$A$300,0))&"" -> 회원가입 | C32: =INDEX(메뉴구조!$C$5:$C$300,MATCH($A32,메뉴구조!$A$5:$A$300,0))&"" -> 투자정보 입력 2 | D32: =INDEX(메뉴구조!$D$5:$D$300,MATCH($A32,메뉴구조!$A$5:$A$300,0))&"" -> — | E32: =INDEX(메뉴구조!$E$5:$E$300,MATCH($A32,메뉴구조!$A$5:$A$300,0))&"" -> — | F32: =INDEX(메뉴구조!$G$5:$G$300,MATCH($A32,메뉴구조!$A$5:$A$300,0))&"" -> 회원가입 / 투자정보 입력 2 | G32: 1 | H32: 뒤로가기 버튼 | I32: - 화면 좌측 상단의 화살표 아이콘 - 클릭 시 이전 단계(투자정보 입력 1)로 돌아감 - 입력 중이던 내용은 저장되지 않을 수 있음(별도 확인 팝업 여부는 미확인) | K32: 유지
A33: S007 | B33: =INDEX(메뉴구조!$B$5:$B$300,MATCH($A33,메뉴구조!$A$5:$A$300,0))&"" -> 회원가입 | C33: =INDEX(메뉴구조!$C$5:$C$300,MATCH($A33,메뉴구조!$A$5:$A$300,0))&"" -> 투자정보 입력 2 | D33: =INDEX(메뉴구조!$D$5:$D$300,MATCH($A33,메뉴구조!$A$5:$A$300,0))&"" -> — | E33: =INDEX(메뉴구조!$E$5:$E$300,MATCH($A33,메뉴구조!$A$5:$A$300,0))&"" -> — | F33: =INDEX(메뉴구조!$G$5:$G$300,MATCH($A33,메뉴구조!$A$5:$A$300,0))&"" -> 회원가입 / 투자정보 입력 2 | G33: 2 | H33: 진행 단계 표시 (03/03) | I33: - 회원가입 내 투자정보 입력 절차의 마지막 단계(3단계 중 3단계)임을 나타내는 텍스트 및 진행 바 - 사용자 조작 요소 아님, 단순 안내용 UI | K33: 유지
A34: S007 | B34: =INDEX(메뉴구조!$B$5:$B$300,MATCH($A34,메뉴구조!$A$5:$A$300,0))&"" -> 회원가입 | C34: =INDEX(메뉴구조!$C$5:$C$300,MATCH($A34,메뉴구조!$A$5:$A$300,0))&"" -> 투자정보 입력 2 | D34: =INDEX(메뉴구조!$D$5:$D$300,MATCH($A34,메뉴구조!$A$5:$A$300,0))&"" -> — | E34: =INDEX(메뉴구조!$E$5:$E$300,MATCH($A34,메뉴구조!$A$5:$A$300,0))&"" -> — | F34: =INDEX(메뉴구조!$G$5:$G$300,MATCH($A34,메뉴구조!$A$5:$A$300,0))&"" -> 회원가입 / 투자정보 입력 2 | G34: 3 | H34: 화면 타이틀 | I34: - "투자를 위한 기본정보를 입력해주세요." 안내 문구 - 본 화면이 투자 목적의 기본정보(주소, 국적, 자금출처, 투자목적, 직업)를 수집하는 단계임을 명시 | K34: 유지
A35: S007 | B35: =INDEX(메뉴구조!$B$5:$B$300,MATCH($A35,메뉴구조!$A$5:$A$300,0))&"" -> 회원가입 | C35: =INDEX(메뉴구조!$C$5:$C$300,MATCH($A35,메뉴구조!$A$5:$A$300,0))&"" -> 투자정보 입력 2 | D35: =INDEX(메뉴구조!$D$5:$D$300,MATCH($A35,메뉴구조!$A$5:$A$300,0))&"" -> — | E35: =INDEX(메뉴구조!$E$5:$E$300,MATCH($A35,메뉴구조!$A$5:$A$300,0))&"" -> — | F35: =INDEX(메뉴구조!$G$5:$G$300,MATCH($A35,메뉴구조!$A$5:$A$300,0))&"" -> 회원가입 / 투자정보 입력 2 | G35: 4 | H35: 주소검색 버튼 | I35: - '자택 주소' 라벨 옆에 위치한 보조 버튼 - 클릭 시 우편번호/주소 검색 레이어(다음/카카오 우편번호 서비스 등으로 추정)가 열려 주소를 검색·선택할 수 있음 - 선택 시 하단 주소 표시 필드에 우편번호 및 도로명주소가 자동 입력되는 것으로 추정 - 필수 입력 항목으로 보이며 미입력 시 하단 '확인' 버튼 제출이 제한될 수 있음(추정) | K35: 유지
A36: S007 | B36: =INDEX(메뉴구조!$B$5:$B$300,MATCH($A36,메뉴구조!$A$5:$A$300,0))&"" -> 회원가입 | C36: =INDEX(메뉴구조!$C$5:$C$300,MATCH($A36,메뉴구조!$A$5:$A$300,0))&"" -> 투자정보 입력 2 | D36: =INDEX(메뉴구조!$D$5:$D$300,MATCH($A36,메뉴구조!$A$5:$A$300,0))&"" -> — | E36: =INDEX(메뉴구조!$E$5:$E$300,MATCH($A36,메뉴구조!$A$5:$A$300,0))&"" -> — | F36: =INDEX(메뉴구조!$G$5:$G$300,MATCH($A36,메뉴구조!$A$5:$A$300,0))&"" -> 회원가입 / 투자정보 입력 2 | G36: 5 | H36: 자택 주소 표시 필드 | I36: - 주소검색을 통해 선택된 우편번호 및 도로명주소를 표시하는 읽기전용(비활성) 입력창으로 보임 - 예시: "[07326] 서울 영등포구 국제금융로 10" - 직접 타이핑이 아닌 주소검색 버튼을 통해서만 값이 채워지는 구조로 추정 | K36: 유지
A37: S007 | B37: =INDEX(메뉴구조!$B$5:$B$300,MATCH($A37,메뉴구조!$A$5:$A$300,0))&"" -> 회원가입 | C37: =INDEX(메뉴구조!$C$5:$C$300,MATCH($A37,메뉴구조!$A$5:$A$300,0))&"" -> 투자정보 입력 2 | D37: =INDEX(메뉴구조!$D$5:$D$300,MATCH($A37,메뉴구조!$A$5:$A$300,0))&"" -> — | E37: =INDEX(메뉴구조!$E$5:$E$300,MATCH($A37,메뉴구조!$A$5:$A$300,0))&"" -> — | F37: =INDEX(메뉴구조!$G$5:$G$300,MATCH($A37,메뉴구조!$A$5:$A$300,0))&"" -> 회원가입 / 투자정보 입력 2 | G37: 6 | H37: 상세주소 입력창 | I37: - 도로명주소 하단의 상세주소(건물명, 동/호수 등) 입력 필드 - 현재 "여의"라는 텍스트가 입력 중인 상태로 캡처됨 - 자유 텍스트 입력, 최대 글자수 등 유효성 제약은 화면상 확인 불가 | K37: 유지
A38: S007 | B38: =INDEX(메뉴구조!$B$5:$B$300,MATCH($A38,메뉴구조!$A$5:$A$300,0))&"" -> 회원가입 | C38: =INDEX(메뉴구조!$C$5:$C$300,MATCH($A38,메뉴구조!$A$5:$A$300,0))&"" -> 투자정보 입력 2 | D38: =INDEX(메뉴구조!$D$5:$D$300,MATCH($A38,메뉴구조!$A$5:$A$300,0))&"" -> — | E38: =INDEX(메뉴구조!$E$5:$E$300,MATCH($A38,메뉴구조!$A$5:$A$300,0))&"" -> — | F38: =INDEX(메뉴구조!$G$5:$G$300,MATCH($A38,메뉴구조!$A$5:$A$300,0))&"" -> 회원가입 / 투자정보 입력 2 | G38: 7 | H38: 국적 선택 필드 (필수) | I38: - 라벨 '국적' 옆 빨간 별표(*)로 필수 입력 항목임을 표시 - 현재 값 "내국인 (대한민국)"으로 기본 선택되어 있음 - 클릭 시 국적 선택 목록(내국인/외국인 등)이 열리는 선택형(select) 필드로 추정 - 약관상 만 19세 이상 국내 회원만 이용 가능하다는 가입 자격과 연계된 항목으로 추정 | J38: 만 19세 이상 국내 회원만 서비스 이용이 가능하며, 타인 정보 도용이나 허위 정보 제출 시 가입 거부 또는 이용계약 취소 대상이 될 수 있음(참고 약관 제4조) | K38: 유지
A39: S007 | B39: =INDEX(메뉴구조!$B$5:$B$300,MATCH($A39,메뉴구조!$A$5:$A$300,0))&"" -> 회원가입 | C39: =INDEX(메뉴구조!$C$5:$C$300,MATCH($A39,메뉴구조!$A$5:$A$300,0))&"" -> 투자정보 입력 2 | D39: =INDEX(메뉴구조!$D$5:$D$300,MATCH($A39,메뉴구조!$A$5:$A$300,0))&"" -> — | E39: =INDEX(메뉴구조!$E$5:$E$300,MATCH($A39,메뉴구조!$A$5:$A$300,0))&"" -> — | F39: =INDEX(메뉴구조!$G$5:$G$300,MATCH($A39,메뉴구조!$A$5:$A$300,0))&"" -> 회원가입 / 투자정보 입력 2 | G39: 8 | H39: 자금출처 선택 필드 (필수) | I39: - 라벨 '자금출처' 옆 빨간 별표(*)로 필수 입력 항목임을 표시 - 현재 값 "근로소득(급여)"으로 기본 선택되어 있음 - 클릭 시 자금출처 선택 목록(근로소득, 사업소득, 금융소득 등)이 열리는 선택형 필드로 추정 - 자본시장법상 투자자 정보 확인 절차의 일부로 보이며, 이후 투자자 성향 분석 및 소득적격회원 심사와 연계될 가능성 있음(추정) | K39: 유지
A40: S007 | B40: =INDEX(메뉴구조!$B$5:$B$300,MATCH($A40,메뉴구조!$A$5:$A$300,0))&"" -> 회원가입 | C40: =INDEX(메뉴구조!$C$5:$C$300,MATCH($A40,메뉴구조!$A$5:$A$300,0))&"" -> 투자정보 입력 2 | D40: =INDEX(메뉴구조!$D$5:$D$300,MATCH($A40,메뉴구조!$A$5:$A$300,0))&"" -> — | E40: =INDEX(메뉴구조!$E$5:$E$300,MATCH($A40,메뉴구조!$A$5:$A$300,0))&"" -> — | F40: =INDEX(메뉴구조!$G$5:$G$300,MATCH($A40,메뉴구조!$A$5:$A$300,0))&"" -> 회원가입 / 투자정보 입력 2 | G40: 9 | H40: 투자목적 선택 필드 (필수) | I40: - 라벨 '투자목적' 옆 빨간 별표(*)로 필수 입력 항목임을 표시 - 현재 값 "저축 및 투자"로 기본 선택되어 있음 - 클릭 시 투자목적 선택 목록이 열리는 선택형 필드로 추정 | K40: 유지
...

Sheet 공통 규칙
A1: 공통 규칙 (R-01 ~ R-12) — 기능정의 상세와 디자인 프롬프트에서 참조
A3: 규칙ID | B3: 규칙명 | C3: 내용 | D3: 적용 화면ID
A4: R-01 | B4: 화면 유형 기준 | C4: 전체 페이지(push): 독립 콘텐츠 열람·작성, 긴 문서, 결과 화면, 딥링크 필요 / 바텀시트: 현재 맥락 유지 + 짧은 선택·확인·요약(복수 조건 필터, 기간 선택, 주문 확인·상세, 계좌 변경, 계산기, 신고, 짧은 고지) / 팝업(앵커형): 목록의 단일 선택 정렬·필터 — 트리거 바로 아래에 뜨는 작은 카드 / 다이얼로그(중앙): 예·아니오 확인, 오류, 로그인 안내 / 토스트: 결과 통지. 오버레이 형태 상세와 전문 팝업은 사용하지 않는다. | D4: S027, S029, S032~S042, S050, S057, S064, S069, S083, S084, S126, S136, S152, S079, S116, S122, S149(팝업)
A5: R-02 | B5: 정렬 팝업 · 필터 바텀시트 | C5: 정렬만 있는 경우(또는 단일 선택 1개 섹션) = 정렬·필터 팝업: 트리거(정렬명+▾) 바로 아래에 뜨는 작은 카드, 현재 선택에 체크, 항목 탭 시 즉시 적용·닫힘(적용 버튼 없음), 바깥 탭·뒤로가기로 닫힘, 딤 없음. 복수 섹션 또는 복수 선택 필터·기간 선택 = 필터 바텀시트(핸들·타이틀·X·섹션+칩·하단 [초기화][적용]). 목록 상단 행: 좌 '총 N건', 우 [정렬 트리거(텍스트+▾)] [필터 아이콘(바텀시트가 있는 목록만, 적용 시 점 배지)]. 네이티브 select 드롭다운 사용 금지. 폼 입력 항목의 옵션 선택(직업·거래목적 등)은 기존 바텀시트를 유지한다. | D5: 팝업: S022, S078, S079, S087(정렬), S092, S116, S121, S122, S149 / 바텀시트: S015, S077, S087(필터), S088, S090(기간)
A6: R-03 | B6: 탭·세그먼트 위계 | C6: 2뎁스(화면 주 탭)=언더라인 탭, 3뎁스(같은 화면 보기 전환)=세그먼트, 필터=칩(+복수 조건이면 바텀시트). 구매/판매/대기는 세그먼트 형태에 의미색만 예외. | D6: S022, S075, S087, S092, S113, S151
A7: R-04 | B7: 계좌 셀렉터 | C7: '[증권사] 한국ST거래증권 ····1234 ⌄' 단일 컨트롤. 탭 → 계좌 변경 바텀시트(S089). 1개 계좌=chevron 없는 읽기 전용, 미연결=[계좌 연결하기]. 라벨 칩·(?)·[계좌변경 >] 삭제. 연도 뱃지는 연도 셀렉터로 교체. 계좌 관리 메뉴 삭제(내 자산 계좌 셀렉터가 유일한 진입점). | D7: S075, S087, S089, S090, S091, S112, S140
A8: R-05 | B8: 주문 카드 표기·필터 | C8: 수량 단위는 '개'. 미체결 '미체결 N개' / 부분체결 '체결 N개 · 미체결 M개' / 체결완료 '체결 N개' / 취소 '취소 N개' / 부분체결 후 취소·만료 '체결 N개 · 취소 M개'. 수정·취소 아이콘은 미체결 잔량이 있는 카드에만 노출(부분체결 포함). 필터는 수량 기반 포함 관계: 미체결=잔량 있는 모든 주문, 체결=체결 수량 있는 모든 주문. 카드 탭 → 주문 상세 시트(체결 건별 내역). | D8: S043, S075, S077, S088, S140, S152
A9: R-06 | B9: AI매칭 예상 체결 내역 | C9: 명칭 '예상 체결 내역'. 수량 입력 전부터 고정 높이 영역으로 상시 노출, 입력 시 실시간 갱신(예상 평균 체결가·총 주문금액·체결 가능 수량), [자세히]로 호가 구간별 내역, 체결 불가·일부 가능은 영역 내 인라인 안내. 링크·chevron·자동 펼침 삭제. | D9: S034, S040, S052~S056, S060, S066~S068
A10: R-07 | B10: 검색 영역 | C10: 홈·백년가게(탐색)·거래 1뎁스에만 노출(MY·더보기·알림·하위 화면 제외). 필드는 진입 버튼이며 탭 → 검색 홈(S150) → 결과(S151, 세그먼트 종목|가게). 로그인 불필요. | D10: S012, S015, S023, S150, S151
A11: R-08 | B11: MY 허브·비로그인 미리보기 | C11: MY 메인은 스크롤 허브(프로필 → 내 자산 → 관심 → 활동 → 내 정보·자격 신청). 비로그인은 로그인 화면으로 바로 보내지 않고 가치 안내 + 흐린 카드 프리뷰를 보여준다. | D11: S112, S113
A12: R-09 | B12: 재인증 규칙 | C12: 재인증은 '내 정보' 진입에만 적용. 유효 5분, 앱이 백그라운드로 가거나 시간이 지나면 초기화('탭 이동 즉시 초기화' 규칙 삭제). 내 정보 하위 화면 왕복은 재인증 생략. MY 허브 요약(등급·투자성향 칩·자격 상태·내 자산)은 게이트 밖. 휴대폰·비밀번호 변경은 본인인증(MOK)을 추가하고 이유를 안내한다. | D12: S093, S112, S123
A13: R-10 | B13: 투자성향 칩 상태 | C13: 미실시 / 유효(유형명·만료월) / 만료 임박(D-30 이내, D-N 표시) / 만료(경고색, 재실시 안내). 칩 탭: 유효·임박=결과 화면, 미실시·만료=안내 다이얼로그 후 설문. 최신 결과·인정기간·재분석은 내 정보 > 투자 성향 분석. 이력 목록은 다음 단계. | D13: S101, S102, S112
A14: R-11 | B14: 투자자 자격 상태 | C14: 정본 화면은 MY > 내 정보 > 투자자 자격 신청(S124) 1개. 상태: 미신청 / 심사 중(재신청 차단) / 승인(만료일, 만료 30일 전 갱신) / 반려(사유) / 만료. 진입점: MY 허브 행, 더보기 조건부 배너, 거래 한도 [한도 늘리기], 한도 초과 안내. 제출 서류는 결과 화면에 보여주지 않는다. 명칭은 '투자자 자격 신청', 상세 화면 내 법령명칭(소득적격투자자) 병기. | D14: S091, S093, S112, S124, S125, S126, S127
A15: R-12 | B15: 관심 아이콘·용어 통일 | C15: 관심 표시는 앱 전체에서 하트(♡/♥). 북마크·스크랩 아이콘 사용 금지. 용어: '이벤트'(이벤트·혜택 아님), '손익 현황'(나의 수익 아님), '예상 체결 내역'(주문예정내역 아님), '내 정보'(내정보 아님), '약관 및 정책'(정책 아님). | D15: S012, S022, S087, S092, S127, S142

Sheet 확인 필요 목록
A1: 확인이 필요한 항목 (v2 신규·변경 관련)
A2: v1의 '화면구분 추정' 항목은 메뉴구조 시트 O열(확인 필요)에 그대로 이어받았습니다.
A3: No | B3: 대상 화면 | C3: 확인 내용 | D3: 확인 주체(제안)
A4: 확인-01 | B4: S023 거래 > 종목 | C4: 2Depth '전체'를 '종목'으로 변경하고 세그먼트를 제거했습니다. 탭 이름 자체를 '종목'으로도 바꿀지 확인이 필요합니다. | D4: 기획
A5: 확인-02 | B5: S087 내 자산 > 거래 한도 | C5: 거래 한도 화면은 기존에 계좌 게이트가 없어 미연결 상태에서도 0원으로 보였습니다(U-09). 내 자산 탭으로 옮기면서 동일하게 게이트를 적용할지 결정이 필요합니다. | D5: 기획·개발
A6: 확인-03 | B6: S102 투자 성향 분석 | C6: '이력 관리'를 과거 결과 목록까지 뜻하는지 확인이 필요합니다. 이번 v2에는 최신 결과·인정기간만 반영했고 이력 목록은 다음 단계로 뒀습니다. | D6: 기획
A7: 확인-04 | B7: S102 재실시 정책 | C7: [다시 분석하기] 도중 이탈 시 기존 결과를 유지하고, 6문항 완료 시점에 교체하는 정책으로 정의했습니다. 확정이 필요합니다. | D7: 기획·컴플라이언스
A8: 확인-05 | B8: S124 반려 사유 | C8: 반려 사유 문구가 소득 정보와 연결될 수 있어 노출 수준을 컴플라이언스와 확인해야 합니다. | D8: 컴플라이언스
A9: 확인-06 | B9: S150·S151 검색 | C9: 최근 검색어의 로그아웃 시 삭제 여부, 추천 목록 노출 기준, 비상장 백년가게를 검색 대상에 포함할지 확정이 필요합니다. | D9: 기획
A10: 확인-07 | B10: S015 백년가게 검색 | C10: '내 주변'(지도)·'백년가게란?' 탭에서는 검색 영역을 노출하지 않도록 정의했습니다. 지도에서도 검색이 필요한지 확인이 필요합니다. | D10: 기획·디자인
A11: 확인-08 | B11: S055 AI매칭 | C11: 일부 수량만 체결 가능한 경우 '[M개로 조정]' 버튼은 제안 사항입니다. 도입 여부 결정이 필요합니다. | D11: 기획
A12: 확인-09 | B12: S088 부분체결 카드 | C12: '체결률 바·평균 체결가'와 '부분체결 후 취소·만료' 상태 배지 명칭(체결완료로 부르면 전량 체결로 오해될 수 있음)은 제안 사항입니다. 확정이 필요합니다. | D12: 기획
A13: 확인-10 | B13: S128 이용안내 | C13: 이용안내 탭 4종(계좌연결/거래시작/가디언이란?/가디언혜택)과 홈 빠른 안내 카드 4종(백년가게란/주문방법/가디언이란/가디언혜택)의 이름·구성이 다르고 콘텐츠가 모두 '준비 중'입니다. 출시 전 정리가 필요합니다. | D13: 기획·콘텐츠
A14: 확인-11 | B14: 딥링크·URL | C14: /trade?tab=holding 등 거래 탭 하위 경로와 /my/activity 직접 진입 경로는 새 경로로 리다이렉트가 필요합니다. 개발 확인이 필요합니다. | D14: 개발
... A17: 확인-14 | B17: S023 거래 목록 | C17: 필터 아이콘·바텀시트를 없애고 '정렬 팝업 + ♡관심만 칩'으로 정의했습니다. 향후 업종 등 복수 조건 필터가 필요해지면 바텀시트를 다시 추가합니다. | D17: 기획

Sheet 디자인 프롬프트
A1: 디자인 수정 프롬프트 (Google Stitch용, v2 기준)
A2: 같은 내용이 별도 파일(한국ST거래_디자인프롬프트_v2.md)에도 있습니다. 복사는 md 파일을 권장합니다(여기서는 셀 높이 제한 때문에 문단 단위로 행을 나눴습니다). 프롬프트는 엑셀 없이도 쓸 수 있도록 값과 규칙을 본문에 넣었습니다.
A3: 구분 | B3: 프롬프트
A4: 0. 사용 순서 | B4: [Stitch 사용 순서] 1. 새 프로젝트에서 플랫폼을 'Mobile'로 선택합니다. 이미지 입력이 가능한 모드에서는 기존 캡처(Git images 폴더의 해당 번호 PNG)를 참고 이미지로 함께 올립니다. 2. 아래 'DESIGN.md' 블록을 프로젝트의 DESIGN.md(디자인 시스템)에 붙여 넣습니다. 지원되지 않으면 각 프롬프트 맨 앞에 붙입니다. 3. 프롬프트는 한 번에 화면 1~3개씩 입력합니다(Stitch는 여러 화면을 요청하면 목록 확인 후 생성하고, 한 번에 6개까지만 생성합니다). 4. 생성 후 화면을 선택해 '수정 프롬프트'로 다듬습니다. 여러 화면에 같은 수정을 적용할 때는 Shift로 다중 선택합니다. 5. 프롬프트의 화면ID(S###)는 엑셀 v2의 화면ID와 같습니다. 프레임 이름에 그대로 쓰면 기능정의와 맞추기 쉽습니다. 6. 프롬프트 안의 값은 예시 데이터입니다(기존 캡처의 샘플 값 사용).
A5: 0. DESIGN.md (공통) | B5: # 한국ST거래 Design System (v2)
B6: ## 플랫폼·톤 - Mobile app, 390×844, 라이트 모드 1종, 한국어(해요체). 신뢰감 있고 차분한 금융 앱, 전통 음식점 가게를 다루는 따뜻한 느낌은 일러스트·아이콘 톤으로만 살짝.
B7: ## 색 (기존 캡처에서 눈대로 가져온 근사값 — 원본과 대조해 보정) - Primary: 진한 남색 #2E2A6B (주요 버튼, 선택된 탭·칩) - 배경 #FFFFFF / 섹션 배경 #F5F5F7 / 카드 배경 #FAFAFA + 1px #E5E5EA - 칩·비활성 버튼 배경: 연한 라벤더 #EFEFF6 - 강조 링크: 골드 #B8860B - 상승·매수·구매: 빨강 #E5162B / 하락·매도·판매: 파랑 #2C6FE0 (한국 금융 관습) - 텍스트 #1A1A1A, 보조 텍스트 #8A8A8E
B8: ## 형태 - 카드 라운드 16, 버튼 라운드 12, 칩·세그먼트 라운드 999. 8pt 간격. 터치 영역 최소 44px. - 서체: Pretendard 계열 산세리프. 숫자는 굵게, 금액은 천 단위 쉼표+'원'.
B9: ## 컴포넌트 규칙 (모든 화면에서 동일하게) - 2뎁스 탭: 언더라인 탭(활성=진한 텍스트+2px 남색 밑줄). 3뎁스 보기 전환: 세그먼트(회색 트랙 위 활성 항목만 흰 카드, 높이 36). - 정렬(단일 선택)·단일 선택 필터: 트리거(정렬명+▾) 아래에 뜨는 작은 팝업 카드, 선택 항목에 체크, 탭 즉시 적용. 복수 섹션·복수 선택 필터·기간 선택: 바텀시트(핸들·타이틀·X·섹션별 칩·하단 [초기화][적용]). - 드롭다운 select, 깔때기 아이콘으로 정렬을 여는 방식은 쓰지 않는다. - 짧은 확인·요약은 바텀시트, 독립 콘텐츠·결과 화면은 전체 페이지(← 뒤로가기 + 제목), 예/아니오 확인은 중앙 다이얼로그. 우측 X로 닫는 오버레이 상세는 쓰지 않는다. - 관심 표시는 하트(♡/♥)만. 북마크·스크랩 아이콘 금지. - 계좌 표기는 '[증권사 로고] 한국ST거래증권 ····1234 ⌄' 단일 셀렉터 1종(라벨 칩·(?)·[계좌변경 >] 금지). - 모든 목록 화면에 로딩(스켈레톤)·빈 상태·오류 상태를 함께 고려한다.
B10: ## 금지 - 새로운 색·아이콘 스타일 추가, 투자 권유·수익 보장으로 읽히는 문구, 이미지 생성.
A11: 요청 1-A. 컴포넌트 스타일 시트 | B11: Mobile 스타일 가이드 화면 2장을 디자인해 주세요. 앱: 한국ST거래(투자계약증권 유통 앱). DESIGN.md의 색·형태를 그대로 사용합니다.
B12: [화면 1: 내비게이션·필터 컴포넌트] 위에서 아래 순서로: 1. 섹션 제목 '2뎁스 탭 — 언더라인': 탭 6개(정보/주문/호가/차트/내 주문/커뮤니티) 가로 스크롤, '주문'이 활성 2. 섹션 제목 '3뎁스 세그먼트': [관심종목][관심가게] 2분할, [게시글][댓글] 2분할, 그리고 의미색 예외 [구매][판매][대기](구매 활성=빨강 채움) 3. 섹션 제목 '칩': 활성/비활성 필터 칩 4개(전체/공지/소식/이벤트) 4. 섹션 제목 '정렬 팝업(단일 선택)': 목록 상단 행(좌 '총 50건', 우 '많이 오른순 ▾')과, 트리거 아래로 열린 작은 팝업 카드(많이 오른순✓ · 거래량 많은순 · 거래대금 높은순 · 시가총액 높은순 · 최근 상장순 · 가나다순), 딤 없음 5. 섹션 제목 '필터 바텀시트(복수 조건)': 하단에서 올라온 시트 — 핸들, 타이틀 '필터', 우측 X, 섹션 '주문상태' 칩(전체✓/미체결/체결/취소·만료), 섹션 '구매/판매' 칩(전체✓/구매/판매), 하단 고정 버튼 [초기화](라벤더) [적용](남색) Do not include: 드롭다운 select, 깔때기 아이콘.
B13: [화면 2: 컨테이너 컴포넌트] 1. '페이지 헤더': ← 뒤로가기 + 가운데 제목 '공시' 2. '바텀시트': 핸들, 타이틀 '구매 주문 확인', 우측 X, 본문 3행, 하단 [취소][구매하기] 3. '다이얼로그(중앙)': 제목 '주문을 취소할까요?', 본문 1줄, [닫기][주문 취소] 4. '토스트': '변경되었어요.' 5. '하트 관심 아이콘' 채움/비채움 2상태
A14: 요청 1-B. 적용 화면 (스타일 통일) | B14: 아래 화면을 DESIGN.md의 컴포넌트 규칙에 맞게 각각 Mobile로 디자인해 주세요(참고 이미지가 있으면 구조를 유지하고 스타일만 통일).
B15: [S023 거래 — 종목 목록] 위에서 아래로: 헤더(왼쪽 '거래', 오른쪽 프로필 원형 '하', 알림 벨), 검색 필드(돋보기+'가게명·종목명을 검색해 보세요'), 목록 상단 행(좌 정렬 트리거 '많이 오른순 ▾', 우 '♡ 관심만' 토글 칩), 종목 카드 5개(원형 가게 아이콘, 가게명 작게, 종목명 굵게: '노을다반 서귀포 리모델링 1호' 5,700원 +14.0% 빨강, '고요한상 안동 리모델링 1호' 5,900원 +68.5%, '온정분식 종로 리모델링 1호' 5,000원 0.0%, 우측에 [주문] 버튼과 하트), 하단 탭바 5개(홈/백년가게/거래[활성]/MY/더보기). 필터 아이콘은 넣지 않습니다. [S023-정렬 열림] 같은 화면에서 정렬 트리거 아래로 정렬 팝업 카드가 열린 상태(6개 항목, '많이 오른순' 체크). [S075 종목상세 내 주문] 헤더(← '서귀포 리모델링 1호' 5,700원 +14.0%, 하트), 언더라인 탭 6개('내 주문' 활성), 계좌 셀렉터 행, 나의 평가금 카드, 목록 상단 행(우측 필터 아이콘 — 바텀시트가 있는 목록), 주문 카드 3개, 하단 고정 [판매하기][구매하기].
A16: 요청 2-A. 홈 + 검색 영역 | B16: Mobile 화면 1개: 한국ST거래 앱의 '홈'(S012). 위에서 아래로: 1. 헤더: 좌측 로고 텍스트 '한국ST거래', 우측 프로필 원형 아이콘과 알림 벨 2. 검색 영역(새로 추가): 헤더 바로 아래 전체 폭 필드, 높이 44, 라운드 999, 배경 라벤더, 돋보기 아이콘 + 회색 placeholder '가게명·종목명을 검색해 보세요'. 입력 필드가 아니라 탭하면 검색 화면으로 넘어가는 버튼처럼 보여야 함 3. 메인 배너 캐러셀(페이지 표시 '1/2') 4. 빠른 안내 원형 카드 4개(백년가게란/주문방법/가디언이란/가디언혜택) 5. 섹션 '가디언 픽' 종목 카드 가로 스크롤(가게명, 종목명, 현재가, 등락률, [주문], 하트) 6. 섹션 '지금 가장 핫한 가게' 대형 카드 — 우측 상단에 하트 관심 아이콘(북마크 금지) 7. 섹션 '이벤트' (제목은 '이벤트·혜택'이 아니라 '이벤트') 8. 하단 탭바 5개(홈 활성) 검색 영역은 화면 스크롤과 함께 위로 사라지고, 다른 콘텐츠가 접힘선 아래로 과하게 밀리지 않도록 간격을 조정.
A17: 요청 2-B. 검색 홈 / 검색 결과 | B17: Mobile 화면 4개를 디자인해 주세요.
B18: [S150-a 검색 홈] 상단: ← 뒤로가기 + 입력창(포커스 상태, 커서, 우측 지우기 X, placeholder '가게명·종목명을 검색해 보세요'). 아래: '최근 검색어' 제목과 우측 텍스트 [전체 삭제], 칩 5개(각 칩 우측에 작은 X): 서귀포, 고요한상, 리모델링 1호, 분점개설, 화덕담. 그 아래 '많이 찜한 종목' 리스트 3행(순위 번호, 원형 아이콘, 가게명/종목명, 현재가·등락률). [S150-b 자동완성] 입력창에 '서귀' 입력 상태. 아래에 자동완성 리스트 4행(일치 글자 남색 굵게 강조, 종목/가게 구분 라벨 칩), 맨 아래 [전체 결과 보기]. [S151-a 결과 — 종목] 상단 검색창(검색어 '리모델링'), 세그먼트 [종목 12][가게 3](종목 활성), 종목 카드 4개(가게명, 종목명, 현재가, 등락률, [주문], 하트). [S151-b 결과 없음] 검색어 '피자', 세그먼트 [종목 0][가게 0], 가운데 빈 상태 일러스트 + '검색 결과가 없어요' + '다른 검색어로 찾아보세요' + 텍스트 링크 '내 주변 지도에서 가게 찾기'. Do not include: 필터·정렬 UI(이번 버전에서는 없음).
A19: 요청 3. 상세 진입 방식 통일 (시트/페이지/다이얼로그) | B19: 같은 주문 흐름을 3장의 Mobile 화면으로 이어서 디자인해 주세요. 진입 방식을 통일합니다: 주문 확인=바텀시트, 주문 완료=전체 페이지, 취소 확인=중앙 다이얼로그.
B20: [S032 주문 확인 — 바텀시트] 배경은 주문 화면(구매 폼, 어둡게 딤 처리). 하단에서 올라온 시트: 핸들, 우측 X, 작은 글씨 '노을다반', 종목명 '서귀포 리모델링 1호', 타이틀 '1개 구매주문'. 표 3행: 개당 금액 4,900원 / 주문 수량 1개 / 총 주문금액 4,900원. 하단 고정 [취소](라벤더) [구매하기](빨강). [S033 주문 완료 — 전체 페이지] 헤더 ← 뒤로가기 + 제목 '주문 완료'. 가운데 체크 아이콘, '구매 주문완료', 종목명, 표 3행(개당 금액/주문 수량/총 구매금액), 안내 '접수 완료이며 체결을 보장하지 않아요. 미체결 주문은 30일간 유효해요.' 하단 [닫기](라벤더) [주문내역](남색). [다이얼로그] 화면 중앙 카드, 제목 '주문을 취소할까요?', 본문 '취소하면 잠긴 금액이 바로 풀려요.', 버튼 [닫기] [주문 취소](빨강). + 추가 화면 [S027 공시 상세 — 전체 페이지] 헤더 ← + '공시'(우측 X 오버레이 금지), 제목 '이익배분내역보고서 제2차', 날짜 2028.12.14, 본문 표(분배 기준일, 지급예정일, 분배 대상 수량 33,600개, 개당 분배금 세전 907원), 하단 첨부파일 1개.
A21: 요청 4. AI매칭 '예상 체결 내역' (5상태) | B21: Mobile 주문 화면(구매, AI매칭 모드) 5개 상태를 디자인해 주세요. 종목: 서귀포 리모델링 1호(노을다반), 현재가 5,700원. 공통 구조(위에서 아래): 헤더(← 종목명 현재가 등락률, 하트), 언더라인 탭 6개('주문' 활성), 구매/판매/대기 세그먼트('구매' 빨강 활성), 카드 '구매 희망가 | AI매칭 ⓘ'에 회색 placeholder '가장 유리한 가격으로 주문', 카드 '수량'(주문가능 59,965,487원 ⓘ), 그 아래 '예상 체결 내역' 영역(항상 보이는 고정 높이 카드, 링크·버튼·chevron이 우측에 떠 있지 않음), 비율 버튼 4개(10%/25%/50%/최대)는 별도 행, 숫자 키패드, 하단 [입력완료]. 영역 하단에 작은 회색 문구 '투자 권유가 아니며 실제 체결가는 접수 시점 호가에 따라 달라질 수 있어요.' [상태 1 입력 전] 수량 비어 있음. 예상 체결 내역 영역에 회색 안내 '수량을 입력하면 예상 체결 내역을 보여드려요'. [상태 2 체결 가능] 수량 3개. 영역에 예상 평균 체결가 5,300원, 예상 총 주문금액 15,900원, 체결 가능 3개, 우측 아래 텍스트 버튼 [자세히 ▾]. [상태 3 자세히 펼침] 상태 2에서 같은 영역 안이 펼쳐져 호가 구간별 표(개당금액/수량/금액) 2행 표시. 화면 전체가 밀려 내려가지 않고 영역 높이만 늘어남. [상태 4 체결 불가] 수량 500개. 영역에 인라인 안내 '지금 바로 체결할 수 있는 호가가 없어요' + 텍스트 버튼 [구매 희망가로 주문하기]. 하단 [구매하기] 비활성. [상태 5 일부 체결 가능] 수량 20개. 영역에 '요청 20개 중 12개 체결 가능' + 버튼 [12개로 조정]. Do not include: '주문예정내역'이라는 이름, 골드색 밑줄 링크.
A22: 요청 5. 계좌 셀렉터 | B22: Mobile 화면 3개를 디자인해 주세요. 앱 전체에서 계좌 표시는 '계좌 셀렉터' 1종만 씁니다.
B23: [컴포넌트 3상태 시트] 한 화면에 3행: (a) 연동 계좌 2개 이상 — '[증권사 로고] 한국ST거래증권 ····1234 ⌄' 탭 가능한 컨트롤 (b) 연동 계좌 1개 — 같은 모양이지만 chevron 없이 텍스트만 (c) 계좌 미연결 — 남색 [계좌 연결하기] 버튼. 라벨 모양 칩, (?) 아이콘, 별도 [계좌변경 >] 알약은 금지. [S087 내 자산 — 보유 탭] 헤더(← '내 자산', 알림 벨), 언더라인 탭 4개(보유 활성/주문 내역/손익 현황/거래 한도), 공통 헤더 카드: 계좌 셀렉터, '나의 평가금' 3,803,000원, 손익 +370,372 (10.7%) 빨강, '계좌잔고' 59,538,164원 ⌄. 목록 상단 행(좌 '총 9건', 우 정렬 트리거 '평가금 높은순 ▾', 필터 아이콘), 보유 종목 카드 3개(가게 아이콘, 가게명, 종목명, 개당 평균단가·보유수량, 현재가·등락률). [S089 계좌 변경 — 바텀시트] 배경은 내 자산 화면(딤). 시트 타이틀 '기본 거래 계좌 설정', 우측 X, 안내문 '주문은 기본 계좌로만 가능해요. 다른 계좌로 거래하려면 기본 계좌를 변경해주세요.', 현재 기본 계좌 카드(체크, 마스킹 번호), 섹션 '거래 계좌 추가'와 미연결 증권사 카드 2개(연계정보 동의 체크박스, 비활성 [계좌 연결하기]), 하단 [완료]. + 추가 화면 [S090 손익 현황]: 같은 공통 헤더, 탭 '손익 현황' 활성, 수익 요약 카드(확정 수익 3,795원 / 분배 수익 0원)와 우측 연도 셀렉터 '2026년 ⌄'(탭하면 단일 선택 팝업), 기간 '2026.08 ~ 2026.09 ▾', 내역 카드 3개. 증권사 뱃지는 넣지 않습니다.
A24: 요청 6-A. MY 허브 (로그인 / 비로그인) | B24: Mobile 화면 3개를 디자인해 주세요. MY는 탭이 없는 세로 스크롤 허브입니다.
B25: [S112-a 로그인·계좌 연결] 헤더 좌측 'MY', 우측 설정 톱니·알림 벨. 위에서 아래로: (1) 얇은 프로필 카드: [일반] 뱃지 + 닉네임 '하늘', 우측 투자성향 칩 '위험중립형 · ~2028.09' (2) 내 자산 카드: 계좌 셀렉터, '나의 평가금' 3,803,000원, 손익 +370,372 (10.7%), 계좌잔고, 하단 바로가기 4개 [보유종목 9][주문 내역][손익 현황][거래 한도] (3) 관심 카드: '관심종목 10 · 관심가게 2' (4) 나의 활동: 커뮤니티 '내가 쓴 글 3건', 문의내역 '전체 1건 · 답변대기 1건'(답변대기 빨강) (5) 목록 행: '내 정보'(자물쇠 아이콘, 재인증 필요 표기), '투자자 자격 신청'(우측 '신청 가능' 상태 텍스트). 하단 탭바(MY 활성). [S112-b 투자성향 칩 4상태] 프로필 카드 4개를 세로로: 미실시(강조색 칩 '투자성향, 지금 확인해요') / 유효('위험중립형 · ~2028.09') / 만료 임박('위험중립형 · D-20', 주황) / 만료('재실시가 필요해요', 경고색). [S112-c 비로그인 미리보기] 로그인 화면으로 넘기지 않고, 상단 큰 카드 '로그인하면 내 자산과 관심 가게를 모아볼 수 있어요' + [로그인](남색) [회원가입](라벨), 아래에 내 자산·관심·활동 카드가 흐리게(잠금 표시) 미리보기로 보임. 하단 탭바 정상.
A26: 요청 6-B. 내 자산 — 주문 내역 / 주문 상세 | B26: Mobile 화면 3개를 디자인해 주세요.
B27: [S088 내 자산 — 주문 내역 탭] 공통 헤더(← '내 자산', 4탭 중 '주문 내역' 활성, 계좌 셀렉터·나의 평가금·계좌잔고 카드는 축소된 형태). 그 아래 '미체결 3건' 칩(탭하면 미체결 필터). 기간 '2026.08 ~ 2026.09 ▾' + 우측 필터 아이콘(복수 조건이라 바텀시트). 주문 카드 4개 — 카드 상단: 날짜, 개당 가격, 방향(구매 빨강/판매 파랑), 우측 수정(연필)·취소(X) 아이콘은 잔량이 있는 카드에만. 카드 본문: 가게 아이콘, 가게명, 종목명. ① '26.09.14 · 개당 6,200원 · 판매 · 미체결 1개 · 만료 D-30' (수정·취소 아이콘 있음) ② '26.09.14 · 개당 500,000원 · 구매 · 체결 1개' (아이콘 없음) ③ '26.09.13 · 개당 5,000원 · 구매 · 체결 10개 · 미체결 2개' — 체결률 바(10/12)와 평균 체결가 5,000원, 수정·취소 아이콘 모두 있음 ④ '26.09.10 · 개당 4,900원 · 구매 · 체결 10개 · 취소 2개' (아이콘 없음) 수량 표기 형식은 반드시 '체결 N개 · 미체결 M개'. 체결완료라고만 쓰지 않습니다. [S088 필터 — 바텀시트] 같은 화면 위로 시트: 타이틀 '필터', 섹션 '주문상태' 칩(전체/미체결 3/체결 5/취소·만료 1), 섹션 '구매/판매' 칩(전체/구매/판매), 하단 [초기화][적용]. [S152 주문 상세 — 바텀시트] 카드 ③을 탭했을 때: 타이틀 '구매 주문 상세', 종목명, 상태 배지 '체결 10개 · 미체결 2개', 요약 표(증권사, 주문일시, 주문가 5,000원, 주문 수량 12개, 체결 수량 10개, 미체결 수량 2개, 총 주문금액 60,000원, 수수료), '체결 내역' 리스트 3행(일시, 체결가, 수량), '만료 D-27', 하단 [잔량 수정] [잔량 취소].
A28: 요청 6-C. 더보기 / 투자자 자격 신청 | B28: Mobile 화면 3개를 디자인해 주세요.
B29: [S127 더보기] 헤더 '더보기'와 프로필 아이콘·알림. 헤더 바로 아래 조건부 배너 카드 '더 큰 투자의 기회 — 투자자 자격 신청하고 한도를 늘려보세요 >'(일반회원·신청 가능일 때만 보이는 배너). 그 아래 메뉴 8행을 그룹 구분선·그룹 제목 없이 하나의 목록으로 순서대로: 공지사항, 이벤트, 이용안내, 고객센터, 투자자 유의사항, 약관 및 정책, 회사소개(우측 외부링크 아이콘 ↗), 현재 버전정보 v1.0.3(우측 chevron 없음). 하단 법적 고지 문구와 로고, 하단 탭바(더보기 활성). [S131 공지사항 목록] 헤더 ← '공지사항', 유형 칩 [전체✓][공지][소식], 공지 행 5개('[공지] 서비스이용약관 개정 안내' 2026.09.20 빨간 N 배지, '[소식] 신규 종목 상장 안내' …), 무한 스크롤 표시. [S124 투자자 자격 신청 — 상태별 5장 중 대표 3장을 한 화면에 세로로 나열] 각 상태 카드: '심사 중이에요'(신청일 2026.09.25, [신청하기] 비활성) / '소득적격 투자자 승인'(인정 만료일 2027.09.01, [갱신 신청]) / '심사가 반려되었어요'(사유 문구 한 줄, [다시 신청하기]). 공통: 한도 비교표(보유한도 1,000만원→3,000만원, 연간거래한도 4,000만원→8,000만원), 진행절차 4단계(서류준비→서류제출→심사진행→한도변경). 제출 서류를 다시 보여주는 UI는 넣지 않습니다.
